Workbook
Name \0: #REF!
Name \A: '[1]טורים 98'!$HJ$133
Name \A: #REF!
Name \b: #REF!
Name \C: '[1]טורים 98'!$HJ$154
Name \c: #REF!
Name \D: '[1]טורים 98'!#REF!
Name \D: #REF!
Name \E: '[1]טורים 98'!$HJ$155
Name \E: #REF!
Name \F: '[1]טורים 98'!$GS$2
Name \F: #REF!
Name \G: #REF!
Name \H: '[1]טורים 98'!$B$336
Name \H: #REF!
Name \I: #REF!
Name \J: '[1]טורים 98'!$HJ$164
Name \J: #REF!
Name \K: '[1]טורים 98'!$HJ$166
Name \K: #REF!
Name \L: '[1]טורים 98'!$HJ$124
Name \L: #REF!
Name \M: '[1]טורים 98'!$HJ$121
Name \m: #REF!
Name \M2: #REF!
Name \N: #REF!
Name \O: '[1]טורים 98'!$HJ$144
Name \O: #REF!
Name \P: '[1]טורים 98'!$GT$13
Name \P: #REF!
Name \paul: #REF!
Name \Q: '[1]טורים 98'!$HJ$127
Name \q: #REF!
Name \R: '[1]טורים 98'!$HJ$118
Name \R: #REF!
Name \S: '[1]טורים 98'!$HJ$151
Name \S: #REF!
Name \t: #REF!
Name \U: '[1]טורים 98'!$HJ$116
Name \U: #REF!
Name \V: #REF!
Name \W: '[1]טורים 98'!$HJ$113
Name \W: #REF!
Name \X: '[1]טורים 98'!$HJ$146
Name \Y: '[1]טורים 98'!$GT$6
Name \Y: #REF!
Name \Z: '[1]טורים 98'!$HJ$129
Name \Z: #REF!
Name _: #REF!
Name _?ץד_F?S_עכ.ד_Fע?S_GF: #REF!
Name __: {"'1-TheatreBkgs'!$A$1:$L$102"}
Name __: {"'1-TheatreBkgs'!$A$1:$L$102"}
Name ___: {"'1-TheatreBkgs'!$A$1:$L$102"}
Name ___: {"'1-TheatreBkgs'!$A$1:$L$102"}
Name ____: #REF!
Name _____________________nnd1: #REF!
Name ____________________nnd1: #REF!
Name ____________________RIV1: #REF!
Name ___________________nnd1: #REF!
Name ___________________RIV1: #REF!

Sheet Qualitative Assumptions
A1: 1 | B1: 2025 Results were adjusted to the latest estimate > will be updated when Q425 financials will be released
A2: 2 | B2: 2026 Results are according to 2026 approved AOP
A3: 3 | B3: ARC Prices- Please see 'Capex Price Weighted AVG.' sheet
A4: 4 | B4: ARC BOM- Please see 'Neptune COGS+OPEX Build' sheet cells D,E,175,176 with updated ARC BOM cost
A5: 5 | B5: Revenues Growth
A6: 5.a | B6: ARC Quantity- Units increase rate on 100 units each year. If in 2026 250 sold, on 2027 450 units sold and so on. MSaaS/Capex ratio sold is approx. on ~55% Capex ~45% MSaaS > Nanox has two manufacturers that can support the quantities: DAGESH in IL and Fabrinet in Thailand.
A7: 5.b | B7: NIN (Nanox Imaging Network)- New business model in the US only with medical service providers. The medical service providers operates in Nanox's name an imaging facility as part of Works' comp., Imaging room at a Nursing homes or County Jails. The medical service provider is being compensated through a carrier/insurance company. Manox is charging the medical service provider: Nanox > Medical serivce provider > Carrier This is a MSaas based model with an avg. scans of 180 per month with an avg. price of $180 per scan.
A8: 6 | B8: Nanox HIT (Vaso Healthcare IT)- On Dec. 25 Nanox aquired Nanox HIT as part of its vision provide an E2E solution and to be a ONE-STOP-SHOP > Providing RIS and PACS SW.
A9: 7 | B9: AI&HIT, Telerad and OEM Division revenues ramp-up- The increase in revenues from 27-30 is a moderate growth expected based on higher penetration to the market, increase in current custpomer base volumes a price increases.
A10: 8 | B10: Costs- On sheet 'Neptune COGS+OPEX Build', all of the salaries costs, annual increases, gm.%, bonus assumpions were updated.

Sheet Neptune P&L
F1: =9.5/F8 -> 0.15948599 | G1: =29/G8 -> 0.27893965
C2: 2023 | D2: 2024 | E2: 2025 | F2: 2026 | G2: 2027 | H2: 2028 | I2: 2029 | J2: 2030 | K2: CAGR
B3: Instrument | C3: 0 | D3: 0.491304 | E3: ='Neptune_Rev Build'!K36/1000 -> 0.496916 | F3: ='Neptune_Rev Build'!O36/1000 -> 37.611361 | G3: ='Neptune_Rev Build'!S36/1000 -> 73.093141 | H3: ='Neptune_Rev Build'!W36/1000 -> 108.34965 | I3: ='Neptune_Rev Build'!AA36/1000 -> 145.9632 | J3: ='Neptune_Rev Build'!AE36/1000 -> 185.9338
B4: Maintenance / Service | C4: 0 | D4: 0 | E4: ='Neptune_Rev Build'!K39/1000 -> 0 | F4: ='Neptune_Rev Build'!O39/1000 -> 0.258 | G4: ='Neptune_Rev Build'!S39/1000 -> 1.95 | H4: ='Neptune_Rev Build'!W39/1000 -> 4.422 | I4: ='Neptune_Rev Build'!AA39/1000 -> 7.674 | J4: ='Neptune_Rev Build'!AE39/1000 -> 11.706
B5: AI | C5: 0.4 | D5: 1.25 | E5: =SUM('Neptune_Rev Build'!K51:K53)/1000 -> 0.798 | F5: =SUM('Neptune_Rev Build'!O51:O53)/1000 -> 7.816 | G5: =SUM('Neptune_Rev Build'!S51:S53)/1000 -> 11.316 | H5: =SUM('Neptune_Rev Build'!W51:W53)/1000 -> 14.816 | I5: =SUM('Neptune_Rev Build'!AA51:AA53)/1000 -> 18.316 | J5: =SUM('Neptune_Rev Build'!AE51:AE53)/1000 -> 21.816
B6: Teleradiology | C6: 9.2 | D6: 10.5 | E6: =('Neptune_Rev Build'!K55)/1000 -> 10.432 | F6: =('Neptune_Rev Build'!O55)/1000 -> 12.373 | G6: =('Neptune_Rev Build'!S55)/1000 -> 13.373 | H6: =('Neptune_Rev Build'!W55)/1000 -> 14.373 | I6: =('Neptune_Rev Build'!AA55)/1000 -> 15.373 | J6: =('Neptune_Rev Build'!AE55)/1000 -> 16.373
B7: Other Revenue | C7: 0.305 | D7: 1.5 | E7: ='Neptune_Rev Build'!K49/1000 -> 0.445 | F7: ='Neptune_Rev Build'!O49/1000 -> 1.508 | G7: ='Neptune_Rev Build'!S49/1000 -> 4.233 | H7: ='Neptune_Rev Build'!W49/1000 -> 7.12675 | I7: ='Neptune_Rev Build'!AA49/1000 -> 10.315812 | J7: ='Neptune_Rev Build'!AE49/1000 -> 14.021672
B8: Total Revenue | C8: 9.905 | D8: 13.741304 | E8: =SUM(E3:E7) -> 12.171916 | F8: =SUM(F3:F7) -> 59.566361 | G8: =SUM(G3:G7) -> 103.96514 | H8: =SUM(H3:H7) -> 149.0874 | I8: =SUM(I3:I7) -> 197.64202 | J8: =SUM(J3:J7) -> 249.85047 | K8: =(J8/E8)^(1/5)-1 -> 0.83005543
B9: % Growth | C9: 0.15469806 | D9: =D8/C8-1 -> 0.38730984 | E9: =E8/D8-1 -> -0.11420954 | F9: =F8/E8-1 -> 3.8937539 | G9: =G8/F8-1 -> 0.74536667 | H9: =H8/G8-1 -> 0.43401338 | I9: =I8/H8-1 -> 0.32567885 | J9: =J8/I8-1 -> 0.26415664
B11: COGS from AI | C11: -8.9599794 | D11: -8.7466944 | E11: =-'Neptune COGS+OPEX Build'!M145 -> 0 | F11: =-'Neptune COGS+OPEX Build'!N145 -> -0.179 | G11: =-'Neptune COGS+OPEX Build'!O145 -> -0.5983 | H11: =-'Neptune COGS+OPEX Build'!P145 -> -0.8483 | I11: =-'Neptune COGS+OPEX Build'!Q145 -> -1.0983 | J11: =-'Neptune COGS+OPEX Build'!R145 -> -1.3483
B12: COGS from Teleradiology | C12: -7.537 | D12: -8.54 | E12: =-'Neptune COGS+OPEX Build'!M191 -> -7.141 | F12: =-'Neptune COGS+OPEX Build'!N191 -> -8.522 | G12: =-'Neptune COGS+OPEX Build'!O191 -> -9.118143 | H12: =-'Neptune COGS+OPEX Build'!P191 -> -9.7695887 | I12: =-'Neptune COGS+OPEX Build'!Q191 -> -10.542091 | J12: =-'Neptune COGS+OPEX Build'!R191 -> -11.547784
B13: COGS (AI & Teleradiology) | C13: -16.496979 | D13: -17.286694 | E13: =SUM(E11:E12) -> -7.141 | F13: =SUM(F11:F12) -> -8.701 | G13: =SUM(G11:G12) -> -9.716443 | H13: =SUM(H11:H12) -> -10.617889 | I13: =SUM(I11:I12) -> -11.640391 | J13: =SUM(J11:J12) -> -12.896084
B14: Depreciation of Neptune MSaaS Systems | C14: 0 | D14: -0.165 | E14: =-'Neptune COGS+OPEX Build'!M175 -> -0.159 | F14: =-'Neptune COGS+OPEX Build'!N175 -> -0.84407143 | G14: =-'Neptune COGS+OPEX Build'!O175 -> -1.6622143 | H14: =-'Neptune COGS+OPEX Build'!P175 -> -2.5542857 | I14: =-'Neptune COGS+OPEX Build'!Q175 -> -3.8828571 | J14: =-'Neptune COGS+OPEX Build'!R175 -> -5.4685714
B15: COGS from Neptune Capex Systems | C15: 0 | D15: -0.24 | E15: =-'Neptune COGS+OPEX Build'!M176 -> -0.312 | F15: =-'Neptune COGS+OPEX Build'!N176 -> -14.6265 | G15: =-'Neptune COGS+OPEX Build'!O176 -> -14.94 | H15: =-'Neptune COGS+OPEX Build'!P176 -> -17.94 | I15: =-'Neptune COGS+OPEX Build'!Q176 -> -20.94 | J15: =-'Neptune COGS+OPEX Build'!R176 -> -23.94
B16: COGS from System Maintenance & Service | C16: 0 | D16: 0 | E16: =-'Neptune COGS+OPEX Build'!M177 -> -0.01490748 | F16: =-'Neptune COGS+OPEX Build'!N177 -> -1.1360808 | G16: =-'Neptune COGS+OPEX Build'!O177 -> -2.2512942 | H16: =-'Neptune COGS+OPEX Build'!P177 -> -3.3831496 | I16: =-'Neptune COGS+OPEX Build'!Q177 -> -4.6091161 | J16: =-'Neptune COGS+OPEX Build'!R177 -> -5.9291939
B17: COGS Other (ARC Salaries, shipping, Installations, SW, Overhead, NIN Costs) | C17: 0 | D17: -0.74714286 | E17: =E18-SUM(E13:E16) -> -3.8750925 | F17: =F18-SUM(F13:F16) -> -12.821348 | G17: =G18-SUM(G13:G16) -> -18.383261 | H17: =H18-SUM(H13:H16) -> -23.914914 | I17: =I18-SUM(I13:I16) -> -29.458113 | J17: =J18-SUM(J13:J16) -> -34.998922
B18: Total COGS | C18: -16.496979 | D18: -18.438837 | E18: =-'Neptune COGS+OPEX Build'!M205 -> -11.502 | F18: =-'Neptune COGS+OPEX Build'!N205 -> -38.129 | G18: =-'Neptune COGS+OPEX Build'!O205 -> -46.953212 | H18: =-'Neptune COGS+OPEX Build'!P205 -> -58.410238 | I18: =-'Neptune COGS+OPEX Build'!Q205 -> -70.530477 | J18: =-'Neptune COGS+OPEX Build'!R205 -> -83.232771
B20: Gross Profit | C20: -6.5919794 | D20: -4.6975332 | E20: =E8+E18 -> 0.669916 | F20: =F8+F18 -> 21.437361 | G20: =G8+G18 -> 57.011928 | H20: =H8+H18 -> 90.677165 | I20: =I8+I18 -> 127.11154 | J20: =J8+J18 -> 166.6177
B21: % Margin | C21: -0.66552038 | D21: -0.34185498 | E21: =E20/E$8 -> 0.055037843 | F21: =F20/F$8 -> 0.35989039 | G21: =G20/G$8 -> 0.54837543 | H21: =H20/H$8 -> 0.6082148 | I21: =I20/I$8 -> 0.64314027 | J21: =J20/J$8 -> 0.66686966
B23: S&M | C23: -4.168 | D23: -4.3830057 | E23: =-'Neptune COGS+OPEX Build'!M40 -> -7.4026609 | F23: =-'Neptune COGS+OPEX Build'!N40 -> -16.528202 | G23: =-'Neptune COGS+OPEX Build'!O40 -> -19.57863 | H23: =-'Neptune COGS+OPEX Build'!P40 -> -22.033477 | I23: =-'Neptune COGS+OPEX Build'!Q40 -> -24.501412 | J23: =-'Neptune COGS+OPEX Build'!R40 -> -26.989853
B24: % Margin | C24: 0.42079758 | D24: 0.31896578 | E24: =-E23/E$8 -> 0.60817548 | F24: =-F23/F$8 -> 0.27747544 | G24: =-G23/G$8 -> 0.18831918 | H24: =-H23/H$8 -> 0.14778899 | I24: =-I23/I$8 -> 0.12396864 | J24: =-J23/J$8 -> 0.10802403
B25: G&A | C25: -25.78 | D25: -23.28841 | E25: =-'Neptune COGS+OPEX Build'!M129 -> -17.169842 | F25: =-'Neptune COGS+OPEX Build'!N129 -> -20.691196 | G25: =-'Neptune COGS+OPEX Build'!O129 -> -21.613191 | H25: =-'Neptune COGS+OPEX Build'!P129 -> -22.572988 | I25: =-'Neptune COGS+OPEX Build'!Q129 -> -23.470267 | J25: =-'Neptune COGS+OPEX Build'!R129 -> -24.61871
B26: % Margin | C26: 2.6027259 | D26: 1.6947744 | E26: =-E25/E$8 -> 1.4106112 | F26: =-F25/F$8 -> 0.34736378 | G26: =-G25/G$8 -> 0.20788882 | H26: =-H25/H$8 -> 0.15140775 | I26: =-I25/I$8 -> 0.1187514 | J26: =-J25/J$8 -> 0.098533775
B27: R&D | C27: -26.049 | D27: -20.930979 | E27: =-'Neptune COGS+OPEX Build'!M74 -> -20.472703 | F27: =-'Neptune COGS+OPEX Build'!N74 -> -23.365872 | G27: =-'Neptune COGS+OPEX Build'!O74 -> -24.975895 | H27: =-'Neptune COGS+OPEX Build'!P74 -> -25.211416 | I27: =-'Neptune COGS+OPEX Build'!Q74 -> -25.618464 | J27: =-'Neptune COGS+OPEX Build'!R74 -> -26.332085
B28: % Margin | C28: 2.6298839 | D28: 1.5232164 | E28: =-E27/E$8 -> 1.6819622 | F28: =-F27/F$8 -> 0.39226623 | G28: =-G27/G$8 -> 0.24023336 | H28: =-H27/H$8 -> 0.16910494 | I28: =-I27/I$8 -> 0.12962054 | J28: =-J27/J$8 -> 0.10539138
B30: Operating Income/(Loss) | C30: -62.588979 | D30: -53.299928 | E30: =E20+E23+E25+E27 -> -44.375289 | F30: =F20+F23+F25+F27 -> -39.147909 | G30: =G20+G23+G25+G27 -> -9.1557868 | H30: =H20+H23+H25+H27 -> 20.859284 | I30: =I20+I23+I25+I27 -> 53.521397 | J30: =J20+J23+J25+J27 -> 88.677049
B31: % Margin | C31: -6.3189278 | D31: -3.8788115 | E31: =E30/E$8 -> -3.6457111 | F31: =F30/F$8 -> -0.65721506 | G31: =G30/G$8 -> -0.088065929 | H31: =H30/H$8 -> 0.13991312 | I31: =I30/I$8 -> 0.27079969 | J31: =J30/J$8 -> 0.35492048
B33: OPEX % | C33: =-(C23+C25+C27)/C$8 -> 5.6534074 | D33: =-(D23+D25+D27)/D$8 -> 3.5369565 | E33: =-(E23+E25+E27)/E$8 -> 3.700749 | F33: =-(F23+F25+F27)/F$8 -> 1.0171055 | G33: =-(G23+G25+G27)/G$8 -> 0.63644136 | H33: =-(H23+H25+H27)/H$8 -> 0.46830168 | I33: =-(I23+I25+I27)/I$8 -> 0.37234058 | J33: =-(J23+J25+J27)/J$8 -> 0.31194918
B35: D&A | C35: 11.81 | D35: 11.921 | E35: ='Neptune COGS+OPEX Build'!M33+'Neptune COGS+OPEX Build'!M32+'Neptune COGS+OPEX Build'!M67+'Neptune COGS+OPEX Build'!M124 -> 1.4959423 | F35: ='Neptune COGS+OPEX Build'!N33+'Neptune COGS+OPEX Build'!N32+'Neptune COGS+OPEX Build'!N67+'Neptune COGS+OPEX Build'!N124 -> 1.4959423 | G35: ='Neptune COGS+OPEX Build'!O33+'Neptune COGS+OPEX Build'!O32+'Neptune COGS+OPEX Build'!O67+'Neptune COGS+OPEX Build'!O124 -> 1.4959423 | H35: ='Neptune COGS+OPEX Build'!P33+'Neptune COGS+OPEX Build'!P32+'Neptune COGS+OPEX Build'!P67+'Neptune COGS+OPEX Build'!P124 -> 1.4959423 | I35: ='Neptune COGS+OPEX Build'!Q33+'Neptune COGS+OPEX Build'!Q32+'Neptune COGS+OPEX Build'!Q67+'Neptune COGS+OPEX Build'!Q124 -> 1.4959423 | J35: ='Neptune COGS+OPEX Build'!R33+'Neptune COGS+OPEX Build'!R32+'Neptune COGS+OPEX Build'!R67+'Neptune COGS+OPEX Build'!R124 -> 1.4959423
B37: EBITDA | C37: -50.778979 | D37: -41.378928 | E37: =E30+E35 -> -42.879347 | F37: =F30+F35 -> -37.651967 | G37: =G30+G35 -> -7.6598445 | H37: =H30+H35 -> 22.355226 | I37: =I30+I35 -> 55.01734 | J37: =J30+J35 -> 90.172991
B38: % Margin | C38: -5.1266006 | D38: -3.0112811 | E38: =E37/E8 -> -3.52281 | F38: =F37/F8 -> -0.63210118 | G38: =G37/G8 -> -0.073677046 | H38: =H37/H8 -> 0.14994712 | I38: =I37/I8 -> 0.27836864 | J38: =J37/J8 -> 0.36090783
B40: Stock-based Compensation | C40: 6.838 | D40: 5.908 | E40: ='Neptune COGS+OPEX Build'!M34++'Neptune COGS+OPEX Build'!M68+'Neptune COGS+OPEX Build'!M125+'Neptune COGS+OPEX Build'!M199 -> 6.6272667 | F40: ='Neptune COGS+OPEX Build'!N34++'Neptune COGS+OPEX Build'!N68+'Neptune COGS+OPEX Build'!N125+'Neptune COGS+OPEX Build'!N199 -> 9.4503967 | G40: ='Neptune COGS+OPEX Build'!O34++'Neptune COGS+OPEX Build'!O68+'Neptune COGS+OPEX Build'!O125+'Neptune COGS+OPEX Build'!O199 -> 9.8857498 | H40: ='Neptune COGS+OPEX Build'!P34++'Neptune COGS+OPEX Build'!P68+'Neptune COGS+OPEX Build'!P125+'Neptune COGS+OPEX Build'!P199 -> 10.241687 | I40: ='Neptune COGS+OPEX Build'!Q34++'Neptune COGS+OPEX Build'!Q68+'Neptune COGS+OPEX Build'!Q125+'Neptune COGS+OPEX Build'!Q199 -> 10.518238 | J40: ='Neptune COGS+OPEX Build'!R34++'Neptune COGS+OPEX Build'!R68+'Neptune COGS+OPEX Build'!R125+'Neptune COGS+OPEX Build'!R199 -> 10.715434
B41: Other Adjustments | C41: 3.086 | D41: 0 | E41: 0 | F41: 0 | G41: 0 | H41: 0 | I41: 0 | J41: 0
B42: Adj. EBITDA | C42: -40.854979 | D42: -35.470928 | E42: =E37+E40 -> -36.25208 | F42: =F37+F40 -> -28.201571 | G42: =G37+G40 -> 2.2259054 | H42: =H37+H40 -> 32.596914 | I42: =I37+I40 -> 65.535578 | J42: =J37+J40 -> 100.88842
B43: % Margin | C43: -4.1246824 | D43: -2.5813364 | E43: =E42/E8 -> -2.978338 | F43: =F42/F8 -> -0.47344793 | G43: =G42/G8 -> 0.021410112 | H43: =H42/H8 -> 0.21864298 | I43: =I42/I8 -> 0.33158728 | J43: =J42/J8 -> 0.40379522
B44: WC rate from rev. | G44: =SUM('[302]CF 2026'!$N$56:$P$56)/SUM('[302]CF 2026'!$N$2:$P$2) -> -0.11197993 | H44: =G44 -> -0.11197993 | I44: =H44 -> -0.11197993 | J44: =I44 -> -0.11197993
B45: WC | F45: ='[302]CF 2026'!$Q$6/1000000 -> -4.4590332 | G45: =G44*G8 -> -11.642009 | H45: =H44*H8 -> -16.694797 | I45: =I44*I8 -> -22.131939 | J45: =J44*J8 -> -27.978238
B46: Capex | F46: ='[302]CF 2026'!$Q$9/1000000 -> -1.0464832 | G46: =-0.5 -> -0.5 | H46: =G46 -> -0.5 | I46: =H46 -> -0.5 | J46: =I46 -> -0.5
B47: Financing, net | G47: =-3.3 -> -3.3 | H47: 0 | I47: 0 | J47: 0
B48: Tax
...

Sheet Neptune_Rev Build
M1: msaas | N1: =M6+M9+N9 -> 151 | O1: =N1/SUM(N$1:N$2) -> 0.43142857 | Q1: msaas | R1: =Q6+Q9+R9 -> 201 | S1: =R1/SUM(R$1:R$2) -> 0.44666667 | U1: msaas | V1: =U6+U9+V9 -> 251 | W1: =V1/SUM(V$1:V$2) -> 0.45636364 | Y1: msaas | Z1: =Y6+Y9+Z9 -> 301 | AA1: =Z1/SUM(Z$1:Z$2) -> 0.46307692 | AC1: msaas | AD1: =AC6+AC9+AD9 -> 351 | AE1: =AD1/SUM(AD$1:AD$2) -> 0.468
M2: capex | N2: =M12+N12 -> 199 | O2: =N2/SUM(N$1:N$2) -> 0.56857143 | Q2: capex | R2: =Q12+R12 -> 249 | S2: =R2/SUM(R$1:R$2) -> 0.55333333 | U2: capex | V2: =U12+V12 -> 299 | W2: =V2/SUM(V$1:V$2) -> 0.54363636 | Y2: capex | Z2: =Y12+Z12 -> 349 | AA2: =Z2/SUM(Z$1:Z$2) -> 0.53692308 | AC2: capex | AD2: =AC12+AD12 -> 399 | AE2: =AD2/SUM(AD$1:AD$2) -> 0.532
B3: $ in '000s | E3: FY24E | I3: FY25E | M3: FY26E | Q3: FY27E | U3: FY28E | Y3: FY29E | AC3: FY30E
E5: U.S. | F5: EX-US | G5: Total | I5: U.S. | J5: EX-US | K5: Total | M5: U.S. | N5: EX-US | O5: Total | Q5: U.S. | R5: EX-US | S5: Total | U5: U.S. | V5: EX-US | W5: Total | Y5: U.S. | Z5: EX-US | AA5: Total | AC5: U.S. | AD5: EX-US | AE5: Total
B6: NIN Installs | M6: =50 -> 50 | Q6: =M6 -> 50 | U6: =Q6 -> 50 | Y6: =U6 -> 50 | AC6: =Y6 -> 50
B7: NIN Installed Base | I7: 0.001 | M7: =+I7+M6 -> 50.001 | N7: =+J7+N6 -> 0 | O7: =SUM(M7:N7) -> 50.001 | Q7: =+M7+Q6 -> 100.001 | R7: =+N7+R6 -> 0 | S7: =SUM(Q7:R7) -> 100.001 | U7: =+Q7+U6 -> 150.001 | V7: =+R7+V6 -> 0 | W7: =SUM(U7:V7) -> 150.001 | Y7: =+U7+Y6 -> 200.001 | Z7: =+V7+Z6 -> 0 | AA7: =SUM(Y7:Z7) -> 200.001 | AC7: =+Y7+AC6 -> 250.001 | AD7: =+Z7+AD6 -> 0 | AE7: =SUM(AC7:AD7) -> 250.001
B8: NIN Service Contract | M8: =I8+I6 -> 0 | N8: =J8+J6 -> 0 | O8: =SUM(M8:N8) -> 0 | Q8: =M8+M6 -> 50 | R8: =N8+N6 -> 0 | S8: =SUM(Q8:R8) -> 50 | U8: =Q8+Q6 -> 100 | V8: =R8+R6 -> 0 | W8: =SUM(U8:V8) -> 100 | Y8: =U8+U6 -> 150 | Z8: =V8+V6 -> 0 | AA8: =SUM(Y8:Z8) -> 150 | AC8: =Y8+Y6 -> 200 | AD8: =Z8+Z6 -> 0 | AE8: =SUM(AC8:AD8) -> 200
B9: MSaaS Installs | E9: 0 | F9: 0 | G9: =SUM(E9:F9) -> 0 | I9: 13 | J9: 2 | K9: =SUM(I9:J9) -> 15 | M9: 80 | N9: 21 | O9: =SUM(M9:N9) -> 101 | Q9: =M9+30 -> 110 | R9: =N9+20 -> 41 | S9: =SUM(Q9:R9) -> 151 | U9: =Q9+30 -> 140 | V9: =R9+20 -> 61 | W9: =SUM(U9:V9) -> 201 | Y9: =U9+30 -> 170 | Z9: =V9+20 -> 81 | AA9: =SUM(Y9:Z9) -> 251 | AC9: =Y9+30 -> 200 | AD9: =Z9+20 -> 101 | AE9: =SUM(AC9:AD9) -> 301
B10: MSaaS Installed Base | E10: =E9 -> 0 | F10: =F9 -> 0 | G10: =SUM(E10:F10) -> 0 | I10: =+E10+I9 -> 13 | J10: =+F10+J9 -> 2 | K10: =SUM(I10:J10) -> 15 | M10: =+I10+M9 -> 93 | N10: =+J10+N9 -> 23 | O10: =SUM(M10:N10) -> 116 | Q10: =+M10+Q9 -> 203 | R10: =+N10+R9 -> 64 | S10: =SUM(Q10:R10) -> 267 | U10: =+Q10+U9 -> 343 | V10: =+R10+V9 -> 125 | W10: =SUM(U10:V10) -> 468 | Y10: =+U10+Y9 -> 513 | Z10: =+V10+Z9 -> 206 | AA10: =SUM(Y10:Z10) -> 719 | AC10: =+Y10+AC9 -> 713 | AD10: =+Z10+AD9 -> 307 | AE10: =SUM(AC10:AD10) -> 1020
B11: MSaaS Service Contract | E11: 0 | F11: 0 | G11: =SUM(E11:F11) -> 0 | I11: =E11+E9 -> 0 | J11: =F11+F9 -> 0 | K11: =SUM(I11:J11) -> 0 | M11: =I11+I9 -> 13 | N11: =J11+J9 -> 2 | O11: =SUM(M11:N11) -> 15 | Q11: =M11+M9 -> 93 | R11: =N11+N9 -> 23 | S11: =SUM(Q11:R11) -> 116 | U11: =Q11+Q9 -> 203 | V11: =R11+R9 -> 64 | W11: =SUM(U11:V11) -> 267 | Y11: =U11+U9 -> 343 | Z11: =V11+V9 -> 125 | AA11: =SUM(Y11:Z11) -> 468 | AC11: =Y11+Y9 -> 513 | AD11: =Z11+Z9 -> 206 | AE11: =SUM(AC11:AD11) -> 719
B12: Capex Sales | E12: 0 | G12: =SUM(E12:F12) -> 0 | I12: 1 | J12: 1 | K12: =SUM(I12:J12) -> 2 | M12: 145 | N12: 54 | O12: =SUM(M12:N12) -> 199 | Q12: =M12+30 -> 175 | R12: =N12+20 -> 74 | S12: =SUM(Q12:R12) -> 249 | U12: =Q12+30 -> 205 | V12: =R12+20 -> 94 | W12: =SUM(U12:V12) -> 299 | Y12: =U12+30 -> 235 | Z12: =V12+20 -> 114 | AA12: =SUM(Y12:Z12) -> 349 | AC12: =Y12+30 -> 265 | AD12: =Z12+20 -> 134 | AE12: =SUM(AC12:AD12) -> 399
B13: Capex Installed Base | E13: =E12 -> 0 | F13: =F12 -> 0 | G13: =SUM(E13:F13) -> 0 | I13: =+E13+I12 -> 1 | J13: =+F13+J12 -> 1 | K13: =SUM(I13:J13) -> 2 | M13: =+I13+M12 -> 146 | N13: =+J13+N12 -> 55 | O13: =SUM(M13:N13) -> 201 | Q13: =+M13+Q12 -> 321 | R13: =+N13+R12 -> 129 | S13: =SUM(Q13:R13) -> 450 | U13: =+Q13+U12 -> 526 | V13: =+R13+V12 -> 223 | W13: =SUM(U13:V13) -> 749 | Y13: =+U13+Y12 -> 761 | Z13: =+V13+Z12 -> 337 | AA13: =SUM(Y13:Z13) -> 1098 | AC13: =+Y13+AC12 -> 1026 | AD13: =+Z13+AD12 -> 471 | AE13: =SUM(AC13:AD13) -> 1497
B14: Capex Service Contract | E14: 0 | F14: 0 | G14: =SUM(E14:F14) -> 0 | I14: =E14+E12 -> 0 | J14: =F14+F12 -> 0 | K14: =SUM(I14:J14) -> 0 | M14: =I14+I12 -> 1 | N14: =J14+J12 -> 1 | O14: =SUM(M14:N14) -> 2 | Q14: =M14+M12 -> 146 | R14: =N14+N12 -> 55 | S14: =SUM(Q14:R14) -> 201 | U14: =Q14+Q12 -> 321 | V14: =R14+R12 -> 129 | W14: =SUM(U14:V14) -> 450 | Y14: =U14+U12 -> 526 | Z14: =V14+V12 -> 223 | AA14: =SUM(Y14:Z14) -> 749 | AC14: =Y14+Y12 -> 761 | AD14: =Z14+Z12 -> 337 | AE14: =SUM(AC14:AD14) -> 1098
B15: Total Installed Base | E15: =E10+E13 -> 0 | F15: =F10+F13 -> 0 | G15: =G10+G13 -> 0 | I15: =I10+I13+I7 -> 14.001 | J15: =J10+J13+J7 -> 3 | K15: =K10+K13+K7 -> 17 | M15: =M10+M13+M7 -> 289.001 | N15: =N10+N13+N7 -> 78 | O15: =O10+O13+O7 -> 367.001 | Q15: =Q10+Q13+Q7 -> 624.001 | R15: =R10+R13+R7 -> 193 | S15: =S10+S13+S7 -> 817.001 | U15: =U10+U13+U7 -> 1019.001 | V15: =V10+V13+V7 -> 348 | W15: =W10+W13+W7 -> 1367.001 | Y15: =Y10+Y13+Y7 -> 1474.001 | Z15: =Z10+Z13+Z7 -> 543 | AA15: =AA10+AA13+AA7 -> 2017.001 | AC15: =AC10+AC13+AC7 -> 1989.001 | AD15: =AD10+AD13+AD7 -> 778 | AE15: =AE10+AE13+AE7 -> 2767.001
E16: =E5 -> U.S. | F16: =F5 -> EX-US | I16: =I5 -> U.S. | J16: =J5 -> EX-US | M16: =M5 -> U.S. | N16: =N5 -> EX-US | Q16: =Q5 -> U.S. | R16: =R5 -> EX-US | U16: =U5 -> U.S. | V16: =V5 -> EX-US | Y16: =Y5 -> U.S. | Z16: =Z5 -> EX-US | AC16: =AC5 -> U.S. | AD16: =AD5 -> EX-US
B17: Per Scan Price | E17: 30 | F17: 14 | M17: 180 | Q17: 180 | U17: 180 | Y17: 180 | AC17: 180
B18: Scans/Day | E18: 2 | F18: 2 | M18: 9 | Q18: 9 | U18: 9 | Y18: 9 | AC18: 9
B19: Days/Month | E19: 2 | F19: 2 | M19: 20 | Q19: 20 | U19: 20 | Y19: 20 | AC19: 20
B20: Instrument Revenue Per Month | M20: =M17*M18*M19/1000 -> 32.4 | Q20: =Q17*Q18*Q19/1000 -> 32.4 | U20: =U17*U18*U19/1000 -> 32.4 | Y20: =Y17*Y18*Y19/1000 -> 32.4 | AC20: =AC17*AC18*AC19/1000 -> 32.4
B21: Months per Year | E21: 3 | F21: 3 | M21: 12 | Q21: 12 | U21: 12 | Y21: 12 | AC21: 12
B22: Per Instrument Recurring Revenue | E22: =E17*E18*E19*E21/1000 -> 0.36 | F22: =F17*F18*F19*F21/1000 -> 0.168 | M22: =M17*M18*M19*M21/1000 -> 388.8 | Q22: =Q17*Q18*Q19*Q21/1000 -> 388.8 | U22: =U17*U18*U19*U21/1000 -> 388.8 | Y22: =Y17*Y18*Y19*Y21/1000 -> 388.8 | AC22: =AC17*AC18*AC19*AC21/1000 -> 388.8
B23: NIN Revenue | E23: =E22*E2 -> 0 | F23: =F22*F2 -> 0 | G23: =SUM(E23:F23) -> 0 | I23: =IFERROR(AVERAGE(I7,E7)*I20*I21,0) -> 0 | J23: =IFERROR(AVERAGE(J7,F7)*J20*J21,0) -> 0 | K23: =SUM(I23:J23) -> 0 | M23: =AVERAGE(M7,I7)*M20*M21 -> 9720.3888 | N23: =AVERAGE(N7,J7)*N20*N21 -> 0 | O23: =SUM(M23:N23) -> 9720.3888 | Q23: =AVERAGE(Q7,M7)*Q20*Q21 -> 29160.389 | R23: =AVERAGE(R7,N7)*R20*R21 -> 0 | S23: =SUM(Q23:R23) -> 29160.389 | U23: =AVERAGE(U7,Q7)*U20*U21 -> 48600.389 | V23: =AVERAGE(V7,R7)*V20*V21 -> 0 | W23: =SUM(U23:V23) -> 48600.389 | Y23: =AVERAGE(Y7,U7)*Y20*Y21 -> 68040.389 | Z23: =AVERAGE(Z7,V7)*Z20*Z21 -> 0 | AA23: =SUM(Y23:Z23) -> 68040.389 | AC23: =AVERAGE(AC7,Y7)*AC20*AC21 -> 87480.389 | AD23: =AVERAGE(AD7,Z7)*AD20*AD21 -> 0 | AE23: =SUM(AC23:AD23) -> 87480.389
E24: =E5 -> U.S. | F24: =F5 -> EX-US | I24: =I5 -> U.S. | J24: =J5 -> EX-US | M24: =M5 -> U.S. | N24: =N5 -> EX-US | Q24: =Q5 -> U.S. | R24: =R5 -> EX-US | U24: =U5 -> U.S. | V24: =V5 -> EX-US | Y24: =Y5 -> U.S. | Z24: =Z5 -> EX-US | AC24: =AC5 -> U.S. | AD24: =AD5 -> EX-US
B25: Per Scan Price | E25: 30 | F25: 14 | I25: 30 | J25: 14 | M25: 30 | N25: 16 | Q25: 30 | R25: 16 | U25: 30 | V25: 16 | Y25: 30 | Z25: 16 | AC25: 30 | AD25: 16
B26: Scans/Day | E26: 2 | F26: 2 | I26: 3 | J26: 4 | M26: 3.3 | N26: 4 | Q26: 7 | R26: 7 | U26: 7 | V26: 7 | Y26: 7 | Z26: 7 | AC26: 7 | AD26: 7
B27: Days/Month | E27: 2 | F27: 2 | I27: 23 | J27: 23 | M27: 23 | N27: 23 | Q27: 23 | R27: 23 | U27: 23 | V27: 23 | Y27: 23 | Z27: 23 | AC27: 23 | AD27: 23
B28: Instrument Revenue Per Month | I28: =I25*I26*I27/1000 -> 2.07 | J28: =J25*J26*J27/1000 -> 1.288 | M28: =M25*M26*M27/1000 -> 2.277 | N28: =N25*N26*N27/1000 -> 1.472 | Q28: =Q25*Q26*Q27/1000 -> 4.83 | R28: =R25*R26*R27/1000 -> 2.576 | U28: =U25*U26*U27/1000 -> 4.83 | V28: =V25*V26*V27/1000 -> 2.576 | Y28: =Y25*Y26*Y27/1000 -> 4.83 | Z28: =Z25*Z26*Z27/1000 -> 2.576 | AC28: =AC25*AC26*AC27/1000 -> 4.83 | AD28: =AD25*AD26*AD27/1000 -> 2.576
B29: Months per Year | E29: 3 | F29: 3 | I29: 12 | J29: 12 | M29: 12 | N29: 12 | Q29: 12 | R29: 12 | U29: 12 | V29: 12 | Y29: 12 | Z29: 12 | AC29: 12 | AD29: 12
B30: Per Instrument Recurring Revenue | E30: =E25*E26*E27*E29/1000 -> 0.36 | F30: =F25*F26*F27*F29/1000 -> 0.168 | I30: =I25*I26*I27*I29/1000 -> 24.84 | J30: =J25*J26*J27*J29/1000 -> 15.456 | M30: =M25*M26*M27*M29/1000 -> 27.324 | N30: =N25*N26*N27*N29/1000 -> 17.664 | Q30: =Q25*Q26*Q27*Q29/1000 -> 57.96 | R30: =R25*R26*R27*R29/1000 -> 30.912 | U30: =U25*U26*U27*U29/1000 -> 57.96 | V30: =V25*V26*V27*V29/1000 -> 30.912 | Y30: =Y25*Y26*Y27*Y29/1000 -> 57.96 | Z30: =Z25*Z26*Z27*Z29/1000 -> 30.912 | AC30: =AC25*AC26*AC27*AC29/1000 -> 57.96 | AD30: =AD25*AD26*AD27*AD29/1000 -> 30.912
B31: MSaaS Revenue | E31: =E30*E10 -> 0 | F31: =F30*F10 -> 0 | G31: =SUM(E31:F31) -> 0 | I31: =AVERAGE(I10,E10)*I28*I29 -> 161.46 | J31: =AVERAGE(J10,F10)*J28*J29 -> 15.456 | K31: =SUM(I31:J31) -> 176.916 | M31: =AVERAGE(M10,I10)*M28*M29 -> 1448.172 | N31: =AVERAGE(N10,J10)*N28*N29 -> 220.8 | O31: =SUM(M31:N31) -> 1668.972 | Q31: =AVERAGE(Q10,M10)*Q28*Q29 -> 8578.08 | R31: =AVERAGE(R10,N10)*R28*R29 -> 1344.672 | S31: =SUM(Q31:R31) -> 9922.752 | U31: =AVERAGE(U10,Q10)*U28*U29 -> 15823.08 | V31: =AVERAGE(V10,R10)*V28*V29 -> 2921.184 | W31: =SUM(U31:V31) -> 18744.264 | Y31: =AVERAGE(Y10,U10)*Y28*Y29 -> 24806.88 | Z31: =AVERAGE(Z10,V10)*Z28*Z29 -> 5115.936 | AA31: =SUM(Y31:Z31) -> 29922.816 | AC31: =AVERAGE(AC10,Y10)*AC28*AC29 -> 35529.48 | AD31: =AVERAGE(AD10,Z10)*AD28*AD29 -> 7928.928 | AE31: =SUM(AC31:AD31) -> 43458.408
B33: Per Instrument Price | E33: 160 | F33: 160 | I33: =E33 -> 160 | J33: =F33 -> 160 | M33: ='Capex Price Weighted AVG.'!D5/1000 -> 127.37931 | N33: ='Capex Price Weighted AVG.'!D9/1000 -> 143.55556 | Q33: ='Capex Price Weighted AVG.'!H5/1000 -> 126.68571 | R33: ='Capex Price Weighted AVG.'!H9/1000 -> 160 | U33: ='Capex Price Weighted AVG.'!L5/1000 -> 126.65854 | V33: ='Capex Price Weighted AVG.'!L9/1000 -> 160 | Y33: ='Capex Price Weighted AVG.'!P5/1000 -> 126.6383 | Z33: ='Capex Price Weighted AVG.'!P9/1000 -> 160 | AC33: ='Capex Price Weighted AVG.'!T5/1000 -> 126.62264 | AD33: ='Capex Price Weighted AVG.'!T9/1000 -> 160
B34: Capex Sales Revenue | E34: =E33*E12 -> 0 | F34: =F33*F12 -> 0 | G34: =SUM(E34:F34) -> 0 | I34: =I33*I12 -> 160 | J34: =J33*J12 -> 160 | K34: =SUM(I34:J34) -> 320 | M34: =M33*M12 -> 18470 | N34: =N33*N12 -> 7752 | O34: =SUM(M34:N34) -> 26222 | Q34: =Q33*Q12 -> 22170 | R34: =R33*R12 -> 11840 | S34: =SUM(Q34:R34) -> 34010 | U34: =U33*U12 -> 25965 | V34: =V33*V12 -> 15040 | W34: =SUM(U34:V34) -> 41005 | Y34: =Y33*Y12 -> 29760 | Z34: =Z33*Z12 -> 18240 | AA34: =SUM(Y34:Z34) -> 48000 | AC34: =AC33*AC12 -> 33555 | AD34: =AD33*AD12 -> 21440 | AE34: =SUM(AC34:AD34) -> 54995
S35: =SUM(Q35:R35) -> 0 | W35: =SUM(U35:V35) -> 0 | AA35: =SUM(Y35:Z35) -> 0 | AE35: =SUM(AC35:AD35) -> 0
B36: Instrument Revenue | E36: =SUM(E31,E34) -> 0 | F36: =SUM(F31,F34) -> 0 | G36: =SUM(E36:F36) -> 0 | I36: =SUM(I31,I34,I23) -> 321.46 | J36: =SUM(J31,J34,J23) -> 175.456 | K36: =SUM(I36:J36) -> 496.916 | M36: =SUM(M31,M34,M23) -> 29638.561 | N36: =SUM(N31,N34,N23) -> 7972.8 | O36: =SUM(M36:N36) -> 37611.361 | Q36: =SUM(Q31,Q34,Q23) -> 59908.469 | R36: =SUM(R31,R34,R23) -> 13184.672 | S36: =SUM(Q36:R36) -> 73093.141 | U36: =SUM(U31,U34,U23) -> 90388.469 | V36: =SUM(V31,V34,V23) -> 17961.184 | W36: =SUM(U36:V36) -> 108349.65 | Y36: =SUM(Y31,Y34,Y23) -> 122607.27 | Z36: =SUM(Z31,Z34,Z23) -> 23355.936 | AA36: =SUM(Y36:Z36) -> 145963.2 | AC36: =SUM(AC31,AC34,AC23) -> 156564.87 | AD36: =SUM(AD31,AD34,AD23) -> 29368.928 | AE36: =SUM(AC36:AD36) -> 185933.8
B38: Maintaince/service Price | E38: 18 | F38: 12 | I38: 18 | J38: 12 | M38: 18 | N38: 12 | Q38: 18 | R38: 12 | U38: 18 | V38: 12 | Y38: 18 | Z38: 12 | AC38: 18 | AD38: 12
B39: Maintaince/service Revenue | E39: 0 | F39: 0 | G39: =SUM(E39:F39) -> 0 | I39: =I38*E10 -> 0 | J39: =J38*F10 -> 0 | K39: =SUM(I39:J39) -> 0 | M39: =M38*I10 -> 234 | N39: =N38*J10 -> 24 | O39: =SUM(M39:N39) -> 258 | Q39: =Q38*M10 -> 1674 | R39: =R38*N10 -> 276 | S39: =SUM(Q39:R39) -> 1950 | U39: =U38*Q10 -> 3654 | V39: =V38*R10 -> 768 | W39: =SUM(U39:V39) -> 4422 | Y39: =Y38*U10 -> 6174 | Z39: =Z38*V10 -> 1500 | AA39: =SUM(Y39:Z39) -> 7674 | AC39: =AC38*Y10 -> 9234 | AD39: =AD38*Z10 -> 2472 | AE39: =SUM(AC39:AD39) -> 11706
B40: % Margin | K40: =K39/K31 -> 0 | O40: =O39/O31 -> 0.15458618 | S40: =S39/S31 -> 0.19651806 | W40: =W39/W31 -> 0.23591217 | AA40: =AA39/AA31 -> 0.25645982 | AE40: =AE39/AE31 -> 0.26936099
B41: Connect | E41: 0 | F41: 1000 | G41: =SUM(E41:F41) -> 1000 | I41: 0 | J41: 0 | K41: =SUM(I41:J41) -> 0 | M41: 0 | N41: 0 | O41: =SUM(M41:N41) -> 0 | Q41: 0 | R41: 0 | S41: =SUM(Q41:R41) -> 0 | U41: 0 | V41: 0 | W41: =SUM(U41:V41) -> 0 | Y41: 0 | Z41: 0 | AA41: =SUM(Y41:Z41) -> 0 | AC41: 0 | AD41: 0 | AE41: =SUM(AC41:AD41) -> 0
B42: % YoY Growth
B43: OEM | E43: 200 | F43: 0 | G43: =SUM(E43:F43) -> 200 | I43: 345 | J43: 0 | K43: =SUM(I43:J43) -> 345 | M43: 1208 | N43: 0 | O43: =SUM(M43:N43) -> 1208 | Q43: =M43+2500 -> 3708 | R43: =N43*(1+R44) -> 0 | S43: =SUM(Q43:R43) -> 3708 | U43: =Q43+2500 -> 6208 | V43: =R43*(1+V44) -> 0 | W43: =SUM(U43:V43) -> 6208 | Y43: =U43+2500 -> 8708 | Z43: =V43*(1+Z44) -> 0 | AA43: =SUM(Y43:Z43) -> 8708 | AC43: =Y43+2500 -> 11208 | AD43: =Z43*(1+AD44) -> 0 | AE43: =SUM(AC43:AD43) -> 11208
...

Sheet Neptune COGS+OPEX Build
A1: Inflation | B1: 0.02 | D1: Fully Loaded | T1: Stubbed for 2024
D2: 0.25 | J2: Inflation | L2: 1 | M2: =+L$2*(1+$B$1) -> 1.02 | N2: =+M$2*(1+$B$1) -> 1.0404 | O2: =+N$2*(1+$B$1) -> 1.061208 | P2: =+O$2*(1+$B$1) -> 1.0824322 | Q2: =+P$2*(1+$B$1) -> 1.1040808 | R2: =+Q$2*(1+$B$1) -> 1.1261624 | T2: 0.75
C3: Salary w/Benefits | D3: Fully Loaded | L3: 2024 | M3: 2025 | N3: 2026 | O3: 2027 | P3: 2028 | Q3: 2029 | R3: 2030
H4: x | J4: S&M
J5: Sales & Customer Success | T5: % of US instruments sold by in-house reps
C6: =D6/(1+$D$2) -> 164000 | D6: 205000 | I6: y | J6: US Salespeople | L6: 4 | M6: 7 | N6: 9 | O6: =N6+2 -> 11 | P6: =O6+2 -> 13 | Q6: =P6+2 -> 15 | R6: =Q6+2 -> 17 | T6: 0.75
C7: =D7/(1+$D$2) -> 118898.4 | D7: 148623 | I7: y | J7: OUS Salespeople | L7: 2 | M7: =3+1 -> 4 | N7: 5 | O7: =N7+1 -> 6 | P7: =O7+1 -> 7 | Q7: =P7+1 -> 8 | R7: =Q7+1 -> 9
C8: 127032 | D8: =C8*(1+D2) -> 158790 | J8: Nanox HIT Salespeople | N8: 5 | O8: =N8+1 -> 6 | P8: =O8+1 -> 7 | Q8: =P8+1 -> 8 | R8: =Q8+1 -> 9
C9: =D9/(1+$D$2) -> 140800 | D9: 176000 | J9: AI - Customer Success | M9: 1 | N9: 2 | O9: =N9+1 -> 3 | P9: =O9+1 -> 4 | Q9: =P9+1 -> 5 | R9: =Q9+1 -> 6
C10: =D10/(1+$D$2) -> 100609.6 | D10: 125762 | I10: y | J10: ARC - Customer Success | L10: 0 | M10: 2 | N10: 26 | O10: =N10+3 -> 29 | P10: =O10+3 -> 32 | Q10: =P10+3 -> 35 | R10: =Q10+3 -> 38
J11: ="Total "&J5&" Headcount" -> Total Sales & Customer Success Headcount | L11: =SUM(L6:L10) -> 6 | M11: =SUM(M6:M10) -> 14 | N11: =SUM(N6:N10) -> 47 | O11: =SUM(O6:O10) -> 55 | P11: =SUM(P6:P10) -> 63 | Q11: =SUM(Q6:Q10) -> 71 | R11: =SUM(R6:R10) -> 79
J13: Marketing
C14: =D14/(1+$D$2) -> 113860 | D14: 142325 | I14: y | J14: Marketing - Communications and Trade Shows | L14: 3 | M14: 3 | N14: 5 | O14: =+N14+1 -> 6 | P14: =+O14+1 -> 7 | Q14: =+P14+1 -> 8 | R14: =+Q14+1 -> 9
J15: ="Total "&J13&" Headcount" -> Total Marketing Headcount | L15: =SUM(L14:L14) -> 3 | M15: =SUM(M14:M14) -> 3 | N15: =SUM(N14:N14) -> 5 | O15: =SUM(O14:O14) -> 6 | P15: =SUM(P14:P14) -> 7 | Q15: =SUM(Q14:Q14) -> 8 | R15: =SUM(R14:R14) -> 9
I17: y | J17: =J5 -> Sales & Customer Success | L17: =SUMPRODUCT($D6:$D10,L6:L10)/10^6*L$2 -> 1.117246 | M17: =SUMPRODUCT($D6:$D10,M6:M10)/10^6*M$2 -> 2.5061563 | N17: =SUMPRODUCT($D6:$D10,N6:N10)/10^6*N$2 -> 7.2868336 | O17: =SUMPRODUCT($D6:$D10,O6:O10)/10^6*O$2 -> 8.7810462 | P17: =SUMPRODUCT($D6:$D10,P6:P10)/10^6*P$2 -> 10.332113 | Q17: =SUMPRODUCT($D6:$D10,Q6:Q10)/10^6*Q$2 -> 11.941709 | R17: =SUMPRODUCT($D6:$D10,R6:R10)/10^6*R$2 -> 13.611557
I18: y | J18: =J13 -> Marketing | L18: =SUMPRODUCT($D14:$D14,L14:L14)/10^6*L$2/2 -> 0.2134875 | M18: =SUMPRODUCT($D14:$D14,M14:M14)/10^6*M$2 -> 0.4355145 | N18: =SUMPRODUCT($D14:$D14,N14:N14)/10^6*N$2 -> 0.74037465 | O18: =SUMPRODUCT($D14:$D14,O14:O14)/10^6*O$2 -> 0.90621857 | P18: =SUMPRODUCT($D14:$D14,P14:P14)/10^6*P$2 -> 1.0784001 | Q18: =SUMPRODUCT($D14:$D14,Q14:Q14)/10^6*Q$2 -> 1.2571064 | R18: =SUMPRODUCT($D14:$D14,R14:R14)/10^6*R$2 -> 1.4425296
J19: Total S&M Salary Costs | L19: =SUM(L17:L18) -> 1.3307335 | M19: =SUM(M17:M18) -> 2.9416708 | N19: =SUM(N17:N18) -> 8.0272083 | O19: =SUM(O17:O18) -> 9.6872648 | P19: =SUM(P17:P18) -> 11.410513 | Q19: =SUM(Q17:Q18) -> 13.198816 | R19: =SUM(R17:R18) -> 15.054087
J20: Stubbing for 2Q-4Q 2024 | L20: =L19*$T$2 -> 0.99805013
D21: =+L$3 -> 2024 | E21: =+M$3 -> 2025 | F21: =+N$3 -> 2026 | G21: =+O$3 -> 2027 | J21: Non-Salary Expenses
D22: 3.5 | E22: 1 | F22: 1 | G22: 1 | I22: y | J22: US In-house Sales Bonus | L22: =L6*$C$6/12*D22/10^6*L$2 -> 0.19133333 | M22: =M6*$C$6/12*E22/10^6*M$2 -> 0.09758 | N22: =N6*$C$6/12*F22/10^6*N$2 -> 0.1279692 | O22: =O6*$C$6/12*$G$22/10^6*O$2 -> 0.15953494 | P22: =P6*$C$6/12*$G$22/10^6*P$2 -> 0.19231211 | Q22: =Q6*$C$6/12*$G$22/10^6*Q$2 -> 0.22633656 | R22: =R6*$C$6/12*$G$22/10^6*R$2 -> 0.26164507
E23: 0.1 | F23: 0.1 | G23: 0.1 | I23: y | J23: US Sales Commissions | L23: 0 | M23: 0 | N23: 0 | O23: 0 | P23: 0 | Q23: 0 | R23: 0 | T23: 0.16 | U23: Instrument Value
D24: 3 | E24: 1 | F24: 1 | G24: 1 | I24: y | J24: OUS Salespeople Bonus | L24: =L7*$C$7/12*D24/10^6*L$2 -> 0.0594492 | M24: =M7*$C$7/12*E24/10^6*M$2 -> 0.040425456 | N24: =N7*$C$7/12*F24/10^6*N$2 -> 0.051542456 | O24: =O7*$C$7/12*$G$24/10^6*O$2 -> 0.063087967 | P24: =P7*$C$7/12*$G$24/10^6*P$2 -> 0.07507468 | Q24: =Q7*$C$7/12*$G$24/10^6*Q$2 -> 0.087515627 | R24: =R7*$C$7/12*$G$24/10^6*R$2 -> 0.10042418
D25: 2.5 | E25: 1 | F25: 1 | G25: 1 | J25: Other Bonuses | L25: =(SUMPRODUCT($C10:$C10,L10:L10)+$C14*L14)/12*D25/10^6*L$2 -> 0.0711625 | M25: =(SUMPRODUCT($C10:$C10,M10:M10)+$C14*M14)/12*E25/10^6*M$2 -> 0.046137932 | N25: =(SUMPRODUCT($C8:$C10,N8:N10)+$C14*N14)/12*F25/10^6*N$2 -> 0.35563556 | O25: =(SUMPRODUCT($C10:$C10,O10:O10)+$C14*O14)/12*$G$25/10^6*O$2 -> 0.31843654 | P25: =(SUMPRODUCT($C10:$C10,P10:P10)+$C14*P14)/12*$G$25/10^6*P$2 -> 0.36230152 | Q25: =(SUMPRODUCT($C10:$C10,Q10:Q10)+$C14*Q14)/12*$G$25/10^6*Q$2 -> 0.40779372 | R25: =(SUMPRODUCT($C10:$C10,R10:R10)+$C14*R14)/12*$G$25/10^6*R$2 -> 0.45496068
F26: 0.04 | J26: Travel | L26: =$F$26*SUM(L19,L22,L24:L25) -> 0.066107141 | M26: 0.337 | N26: 0.457 | O26: =$F$26*SUM(O19,O22,O24:O25) -> 0.40913297 | P26: =$F$26*SUM(P19,P22,P24:P25) -> 0.48160804 | Q26: =$F$26*SUM(Q19,Q22,Q24:Q25) -> 0.55681846 | R26: =$F$26*SUM(R19,R22,R24:R25) -> 0.63484466
D27: 250000 | F27: Annual Increase | G27: 0.05 | J27: Subcontractors | L27: =+$D$27*L$2/10^6 -> 0.25 | M27: 1.237 | N27: 2.167 | O27: =N27*(1+$G$27) -> 2.27535 | P27: =O27*(1+$G$27) -> 2.3891175 | Q27: =P27*(1+$G$27) -> 2.5085734 | R27: =Q27*(1+$G$27) -> 2.634002
F28: 0.03 | J28: Channel Fees | L28: 1.512e-05 | M28: 0 | N28: 0 | O28: 0 | P28: 0 | Q28: 0 | R28: 0
D29: 750000 | F29: Annual Increase | G29: 0.05 | J29: Product Marketing & Conferences | L29: 1 | M29: 0.949 | N29: 1.151 | O29: =N29*(1+$G$27) -> 1.20855 | P29: =O29*(1+$G$27) -> 1.2689775 | Q29: =P29*(1+$G$27) -> 1.3324264 | R29: =Q29*(1+$G$27) -> 1.3990477
J30: Other | L30: 0 | M30: 0.156 | N30: 0.303 | O30: =N30*(1+$G$27) -> 0.31815 | P30: =O30*(1+$G$27) -> 0.3340575 | Q30: =P30*(1+$G$27) -> 0.35076038 | R30: =Q30*(1+$G$27) -> 0.36829839
J31: Overhead | L31: 0 | M31: 0.187 | N31: 0.165 | O31: =+N31*(1+10%)*O$2 -> 0.19260925 | P31: =+O31*(1+10%)*P$2 -> 0.22933509 | Q31: =+P31*(1+10%)*Q$2 -> 0.27852492 | R31: =+Q31*(1+10%)*R$2 -> 0.34503073
J32: Amortization of Intangible Assets | L32: 0.388 | M32: =+L32 -> 0.388 | N32: =+M32 -> 0.388 | O32: =+N32 -> 0.388 | P32: =+O32 -> 0.388 | Q32: =+P32 -> 0.388 | R32: =+Q32 -> 0.388
J33: Depreciation | L33: 0.03018 | M33: =+L33 -> 0.03018 | N33: =+M33 -> 0.03018 | O33: =+N33 -> 0.03018 | P33: =+O33 -> 0.03018 | Q33: =+P33 -> 0.03018 | R33: =+Q33 -> 0.03018
J34: Stock Based Compensation | L34: 0.584 | M34: =M211*M11 -> 1.2926667 | N34: =N211*N11 -> 4.1046667 | O34: =O211*O11 -> 4.5283333 | P34: =P211*P11 -> 4.872 | Q34: =Q211*Q11 -> 5.1356667 | R34: =R211*R11 -> 5.3193333
J35: Total Non-Salary Expenses | L35: =SUM(L22:L34) -> 2.6402473 | M35: =SUM(M22:M34) -> 4.7609901 | N35: =SUM(N22:N34) -> 9.3009939 | O35: =SUM(O22:O34) -> 9.891365 | P35: =SUM(P22:P34) -> 10.622964 | Q35: =SUM(Q22:Q34) -> 11.302596 | R35: =SUM(R22:R34) -> 11.935767
J36: Ex Commissions, Bonus & SBC | L36: =SUM(L26:L33) -> 1.7343023 | M36: =SUM(M26:M33) -> 3.28418 | N36: =SUM(N26:N33) -> 4.66118 | O36: =SUM(O26:O33) -> 4.8219722 | P36: =SUM(P26:P33) -> 5.1212756 | Q36: =SUM(Q26:Q33) -> 5.4452835 | R36: =SUM(R26:R33) -> 5.7994035
J37: Stubbing for 2Q-4Q 2024 | L37: =L35*stub1h24 -> 1.9801855
J38: 1Q 2024 | L38: 0.8
J39: Adjustment | M39: -0.3 | N39: -0.8
H40: x | J40: Total S&M | L40: =SUM(L37,L20)+L38 -> 3.7782356 | M40: =SUM(M35,M19,M39) -> 7.4026609 | N40: =SUM(N35,N19,N39) -> 16.528202 | O40: =SUM(O35,O19,O39) -> 19.57863 | P40: =SUM(P35,P19,P39) -> 22.033477 | Q40: =SUM(Q35,Q19,Q39) -> 24.501412 | R40: =SUM(R35,R19,R39) -> 26.989853
H42: x | J42: R&D
C43: =D43/(1+$D$2) -> 126930.4 | D43: 158663 | J43: ARC - R&D, SW, Algo, V&V, Mechanical | L43: 28 | M43: =L43 -> 28 | N43: 30 | O43: =N43+1 -> 31 | P43: =O43 -> 31 | Q43: =P43 -> 31 | R43: =Q43 -> 31
...

Sheet Capex Price Weighted AVG.
A1: Territory | B1: Units Quantity | C1: 2026 | D1: Weighted Price | F1: Units Quantity | G1: =C1+1 -> 2027 | H1: Weighted Price | J1: Units Quantity | K1: =G1+1 -> 2028 | L1: Weighted Price | N1: Units Quantity | O1: =K1+1 -> 2029 | P1: Weighted Price | R1: Units Quantity | S1: =O1+1 -> 2030 | T1: Weighted Price
A2: Channel Partner | B2: 121 | C2: 120000 | D2: =SUMPRODUCT(B2,C2) -> 14520000 | F2: =F5-F3 -> 157 | G2: =C2 -> 120000 | H2: =SUMPRODUCT(F2,G2) -> 18840000 | J2: =J5-J3 -> 184 | K2: =G2 -> 120000 | L2: =SUMPRODUCT(J2,K2) -> 22080000 | N2: =N5-N3 -> 211 | O2: =K2 -> 120000 | P2: =SUMPRODUCT(N2,O2) -> 25320000 | R2: =R5-R3 -> 238 | S2: =O2 -> 120000 | T2: =SUMPRODUCT(R2,S2) -> 28560000
A3: US X | B3: 14 | C3: 185000 | D3: =SUMPRODUCT(B3,C3) -> 2590000 | F3: =ROUND($A$5*F5,0) -> 18 | G3: =C3 -> 185000 | H3: =SUMPRODUCT(F3,G3) -> 3330000 | J3: =ROUND($A$5*J5,0) -> 21 | K3: =G3 -> 185000 | L3: =SUMPRODUCT(J3,K3) -> 3885000 | N3: =ROUND($A$5*N5,0) -> 24 | O3: =K3 -> 185000 | P3: =SUMPRODUCT(N3,O3) -> 4440000 | R3: =ROUND($A$5*R5,0) -> 27 | S3: =O3 -> 185000 | T3: =SUMPRODUCT(R3,S3) -> 4995000
A4: US 2.2 | B4: 10 | C4: 136000 | D4: =SUMPRODUCT(B4,C4) -> 1360000
A5: =B3/(SUM(B2:B3)) -> 0.1037037 | B5: =SUM(B2:B4) -> 145 | D5: =SUM(D2:D4)/B5 -> 127379.31 | F5: ='Neptune_Rev Build'!Q12 -> 175 | H5: =SUM(H2:H4)/F5 -> 126685.71 | J5: ='Neptune_Rev Build'!U12 -> 205 | L5: =SUM(L2:L4)/J5 -> 126658.54 | N5: ='Neptune_Rev Build'!Y12 -> 235 | P5: =SUM(P2:P4)/N5 -> 126638.3 | R5: ='Neptune_Rev Build'!AC12 -> 265 | T5: =SUM(T2:T4)/R5 -> 126622.64
A7: ROW X | B7: 17 | C7: 160000 | D7: =SUMPRODUCT(B7,C7) -> 2720000 | F7: =F9 -> 74 | G7: =C7 -> 160000 | H7: =SUMPRODUCT(F7,G7) -> 11840000 | J7: =J9 -> 94 | K7: =G7 -> 160000 | L7: =SUMPRODUCT(J7,K7) -> 15040000 | N7: =N9 -> 114 | O7: =K7 -> 160000 | P7: =SUMPRODUCT(N7,O7) -> 18240000 | R7: =R9 -> 134 | S7: =O7 -> 160000 | T7: =SUMPRODUCT(R7,S7) -> 21440000
A8: ROW 2.2 | B8: 37 | C8: 136000 | D8: =SUMPRODUCT(B8,C8) -> 5032000
B9: =SUM(B6:B8) -> 54 | D9: =SUM(D7:D8)/B9 -> 143555.56 | F9: ='Neptune_Rev Build'!R12 -> 74 | H9: =SUM(H7:H8)/F9 -> 160000 | J9: ='Neptune_Rev Build'!V12 -> 94 | L9: =SUM(L7:L8)/J9 -> 160000 | N9: ='Neptune_Rev Build'!Z12 -> 114 | P9: =SUM(P7:P8)/N9 -> 160000 | R9: ='Neptune_Rev Build'!AD12 -> 134 | T9: =SUM(T7:T8)/R9 -> 160000
