Workbook
Name \0: #REF!
Name \A: #REF!
Name \b: #REF!
Name \c: #REF!
Name \D: #REF!
Name \E: #REF!
Name \F: #REF!
Name \G: #REF!
Name \H: #REF!
Name \I: #REF!
Name \J: #REF!
Name \K: #REF!
Name \L: #REF!
Name \m: #REF!
Name \M2: #REF!
Name \N: #REF!
Name \O: #REF!
Name \P: #REF!
Name \paul: #REF!
Name \q: #REF!
Name \R: #REF!
Name \S: #REF!
Name \t: #REF!
Name \U: #REF!
Name \V: #REF!
Name \W: #REF!
Name \X: '[1]טורים 98'!$HJ$146
Name \Y: #REF!
Name \Z: #REF!
Name _: #REF!
Name _?ץד_F?S_עכ.ד_Fע?S_GF: #REF!
Name __: {"'1-TheatreBkgs'!$A$1:$L$102"}
Name ___: {"'1-TheatreBkgs'!$A$1:$L$102"}
Name ____: #REF!
Name _____________________nnd1: #REF!
Name ____________________nnd1: #REF!
Name ____________________RIV1: #REF!
Name ___________________nnd1: #REF!
Name ___________________RIV1: #REF!
Name __________________nnd1: #REF!
Name __________________RIV1: #REF!
Name _________________nnd1: #REF!
Name _________________RIV1: #REF!
Name ________________nnd1: #REF!
Name ________________RIV1: #REF!
Name _______________nnd1: #REF!
Name _______________RIV1: #REF!
Name ______________nnd1: #REF!
Name ______________RIV1: #REF!
Name _____________nnd1: #REF!
Name _____________RIV1: #REF!
Name ____________a1: {"'2ND_QUAR'!$A$1:$P$106"}
Name ____________nnd1: #REF!
Name ____________RIV1: #REF!
Name ___________a1: {"'2ND_QUAR'!$A$1:$P$106"}
Name ___________nnd1: #REF!
Name ___________RIV1: #REF!
Name __________a1: {"'2ND_QUAR'!$A$1:$P$106"}
Name __________nnd1: #REF!
Name __________RIV1: #REF!

Sheet Cover Page

Sheet Customer's Questionnaire
G5: Customer's Questioniere
H6: Name: | I6: GOOGOO DOLLS
G7: Please fill-in the following questionnaire in order to complete the financial model:
G8: 1 | H8: Company's sector | I8: Food-Tech / Ag-Tech
G9: 2 | H9: Upcoming Round | I9: Round C
G10: 3 | H10: Capital Raise Goal | I10: 30000000 | J10: =IF(I10-_xlfn.XLOOKUP(I8&I9,Benchmark_Table!C:C,Benchmark_Table!K:K,0)<0,"Too Low",IF(I10-_xlfn.XLOOKUP(I8&I9,Benchmark_Table!C:C,Benchmark_Table!M:M,0)>0,"Too High",IF(AND(AVERAGE(_xlfn.XLOOKUP(I8&I9,Benchmark_Table!C:C,Benchmark_Table!K:K,0),_xlfn.XLOOKUP(I8&I9,Benchmark_Table!C:C,Benchmark_Table!L:L,0))<I10,AVERAGE(_xlfn.XLOOKUP(I8&I9,Benchmark_Table!C:C,Benchmark_Table!M:M,0),_xlfn.XLOOKUP(I8&I9,Benchmark_Table!C:C,Benchmark_Table!L:L,0))>I10),"Base",IF(AND(_xlfn.XLOOKUP(I8&I9,Benchmark_Table!C:C,Benchmark_Table!L:L,0)>I10,_xlfn.XLOOKUP(I8&I9,Benchmark_Table!C:C,Benchmark_Table!K:K,0)<I10),"Low",IF(_xlfn.XLOOKUP(I8&I9,Benchmark_Table!C:C,Benchmark_Table!K:K,0)-I10=0,"Low",IF(_xlfn.XLOOKUP(I8&I9,Benchmark_Table!C:C,Benchmark_Table!M:M,0)-I10=0,"High","High")))))) -> Too High
G11: 4 | H11: Avg_Years_Since_Founding | I11: 7 | J11: =IF(_xlfn.XLOOKUP(I8&I9,Benchmark_Table!C:C,Benchmark_Table!E:E,0)=I11,"In Benchmark","Not In Benchmark") -> Not In Benchmark
G12: 5 | H12: First Year Financial Model | I12: 2026
G14: 6 | H14: Commercial:
H15: Please define the Customers and Products
G16: 6.a. | H16: Customers: | I16: Type: | J16: Territory
H17: Hungry AF | I17: B2C | J17: US
H18: BULO | I18: Direct | J18: EU
G29: 6.b. | H29: Products: | I29: Revenue Type: | J29: Price: | K29: Cost:
H30: Big MAC | I30: Hardware | J30: 1000 | K30: 500
H31: MCMC | I31: Software / SaaS | J31: 10 | K31: 5
G41: 7 | H41: Lets Scale:
H42: Please specify the Deployment Plan:
H43: Revenue Type | I43: Customer Name | J43: Type | K43: Territory | L43: Product Name | M43: Price | N43: Cost: | O43: ="Q1-"&'Customer''s Questionnaire'!$I$12 -> Q1-2026 | P43: ="Q2-"&'Customer''s Questionnaire'!$I$12 -> Q2-2026 | Q43: ="Q3-"&'Customer''s Questionnaire'!$I$12 -> Q3-2026 | R43: ="Q4-"&'Customer''s Questionnaire'!$I$12 -> Q4-2026 | S43: =I12+1 -> 2027
H44: =_xlfn.XLOOKUP(L44,$H$30:$H$39,$I$30:$I$39,0) -> Hardware | I44: Hungry AF | J44: =_xlfn.XLOOKUP(I44,$H$17:$H$26,$I$17:$I$26,0) -> B2C | K44: =_xlfn.XLOOKUP(I44,$H$17:$H$26,$J$17:$J$26,0) -> US | L44: Big MAC | M44: =_xlfn.XLOOKUP(L44,$H$30:$H$39,$J$30:$J$39,0) -> 1000 | N44: =_xlfn.XLOOKUP(L44,$H$30:$H$39,$K$30:$K$39,0) -> 500 | O44: 10 | P44: 10 | Q44: 10 | R44: 10 | S44: 50
H45: =_xlfn.XLOOKUP(L45,$H$30:$H$39,$I$30:$I$39,0) -> Software / SaaS | I45: BULO | J45: =_xlfn.XLOOKUP(I45,$H$17:$H$26,$I$17:$I$26,0) -> Direct | K45: =_xlfn.XLOOKUP(I45,$H$17:$H$26,$J$17:$J$26,0) -> EU | L45: MCMC | M45: =_xlfn.XLOOKUP(L45,$H$30:$H$39,$J$30:$J$39,0) -> 10 | N45: =_xlfn.XLOOKUP(L45,$H$30:$H$39,$K$30:$K$39,0) -> 5 | O45: 1000 | P45: 1000 | Q45: 1000 | R45: 1000 | S45: 5000
H46: =_xlfn.XLOOKUP(L46,$H$30:$H$39,$I$30:$I$39,0) -> 0 | J46: =_xlfn.XLOOKUP(I46,$H$17:$H$26,$I$17:$I$26,0) -> 0 | K46: =_xlfn.XLOOKUP(I46,$H$17:$H$26,$J$17:$J$26,0) -> 0 | M46: =_xlfn.XLOOKUP(L46,$H$30:$H$39,$J$30:$J$39,0) -> 0 | N46: =_xlfn.XLOOKUP(L46,$H$30:$H$39,$K$30:$K$39,0) -> 0
H47: =_xlfn.XLOOKUP(L47,$H$30:$H$39,$I$30:$I$39,0) -> 0 | J47: =_xlfn.XLOOKUP(I47,$H$17:$H$26,$I$17:$I$26,0) -> 0 | K47: =_xlfn.XLOOKUP(I47,$H$17:$H$26,$J$17:$J$26,0) -> 0 | M47: =_xlfn.XLOOKUP(L47,$H$30:$H$39,$J$30:$J$39,0) -> 0 | N47: =_xlfn.XLOOKUP(L47,$H$30:$H$39,$K$30:$K$39,0) -> 0
H48: =_xlfn.XLOOKUP(L48,$H$30:$H$39,$I$30:$I$39,0) -> 0 | J48: =_xlfn.XLOOKUP(I48,$H$17:$H$26,$I$17:$I$26,0) -> 0 | K48: =_xlfn.XLOOKUP(I48,$H$17:$H$26,$J$17:$J$26,0) -> 0 | M48: =_xlfn.XLOOKUP(L48,$H$30:$H$39,$J$30:$J$39,0) -> 0 | N48: =_xlfn.XLOOKUP(L48,$H$30:$H$39,$K$30:$K$39,0) -> 0
H49: =_xlfn.XLOOKUP(L49,$H$30:$H$39,$I$30:$I$39,0) -> 0 | J49: =_xlfn.XLOOKUP(I49,$H$17:$H$26,$I$17:$I$26,0) -> 0 | K49: =_xlfn.XLOOKUP(I49,$H$17:$H$26,$J$17:$J$26,0) -> 0 | M49: =_xlfn.XLOOKUP(L49,$H$30:$H$39,$J$30:$J$39,0) -> 0 | N49: =_xlfn.XLOOKUP(L49,$H$30:$H$39,$K$30:$K$39,0) -> 0
H50: =_xlfn.XLOOKUP(L50,$H$30:$H$39,$I$30:$I$39,0) -> 0 | J50: =_xlfn.XLOOKUP(I50,$H$17:$H$26,$I$17:$I$26,0) -> 0 | K50: =_xlfn.XLOOKUP(I50,$H$17:$H$26,$J$17:$J$26,0) -> 0 | M50: =_xlfn.XLOOKUP(L50,$H$30:$H$39,$J$30:$J$39,0) -> 0 | N50: =_xlfn.XLOOKUP(L50,$H$30:$H$39,$K$30:$K$39,0) -> 0
H51: =_xlfn.XLOOKUP(L51,$H$30:$H$39,$I$30:$I$39,0) -> 0 | J51: =_xlfn.XLOOKUP(I51,$H$17:$H$26,$I$17:$I$26,0) -> 0 | K51: =_xlfn.XLOOKUP(I51,$H$17:$H$26,$J$17:$J$26,0) -> 0 | M51: =_xlfn.XLOOKUP(L51,$H$30:$H$39,$J$30:$J$39,0) -> 0 | N51: =_xlfn.XLOOKUP(L51,$H$30:$H$39,$K$30:$K$39,0) -> 0
H52: =_xlfn.XLOOKUP(L52,$H$30:$H$39,$I$30:$I$39,0) -> 0 | J52: =_xlfn.XLOOKUP(I52,$H$17:$H$26,$I$17:$I$26,0) -> 0 | K52: =_xlfn.XLOOKUP(I52,$H$17:$H$26,$J$17:$J$26,0) -> 0 | M52: =_xlfn.XLOOKUP(L52,$H$30:$H$39,$J$30:$J$39,0) -> 0 | N52: =_xlfn.XLOOKUP(L52,$H$30:$H$39,$K$30:$K$39,0) -> 0
H53: =_xlfn.XLOOKUP(L53,$H$30:$H$39,$I$30:$I$39,0) -> 0 | J53: =_xlfn.XLOOKUP(I53,$H$17:$H$26,$I$17:$I$26,0) -> 0 | K53: =_xlfn.XLOOKUP(I53,$H$17:$H$26,$J$17:$J$26,0) -> 0 | M53: =_xlfn.XLOOKUP(L53,$H$30:$H$39,$J$30:$J$39,0) -> 0 | N53: =_xlfn.XLOOKUP(L53,$H$30:$H$39,$K$30:$K$39,0) -> 0
H54: =_xlfn.XLOOKUP(L54,$H$30:$H$39,$I$30:$I$39,0) -> 0 | J54: =_xlfn.XLOOKUP(I54,$H$17:$H$26,$I$17:$I$26,0) -> 0 | K54: =_xlfn.XLOOKUP(I54,$H$17:$H$26,$J$17:$J$26,0) -> 0 | M54: =_xlfn.XLOOKUP(L54,$H$30:$H$39,$J$30:$J$39,0) -> 0 | N54: =_xlfn.XLOOKUP(L54,$H$30:$H$39,$K$30:$K$39,0) -> 0
H55: =_xlfn.XLOOKUP(L55,$H$30:$H$39,$I$30:$I$39,0) -> 0 | J55: =_xlfn.XLOOKUP(I55,$H$17:$H$26,$I$17:$I$26,0) -> 0 | K55: =_xlfn.XLOOKUP(I55,$H$17:$H$26,$J$17:$J$26,0) -> 0 | M55: =_xlfn.XLOOKUP(L55,$H$30:$H$39,$J$30:$J$39,0) -> 0 | N55: =_xlfn.XLOOKUP(L55,$H$30:$H$39,$K$30:$K$39,0) -> 0
H56: =_xlfn.XLOOKUP(L56,$H$30:$H$39,$I$30:$I$39,0) -> 0 | J56: =_xlfn.XLOOKUP(I56,$H$17:$H$26,$I$17:$I$26,0) -> 0 | K56: =_xlfn.XLOOKUP(I56,$H$17:$H$26,$J$17:$J$26,0) -> 0 | M56: =_xlfn.XLOOKUP(L56,$H$30:$H$39,$J$30:$J$39,0) -> 0 | N56: =_xlfn.XLOOKUP(L56,$H$30:$H$39,$K$30:$K$39,0) -> 0
H57: =_xlfn.XLOOKUP(L57,$H$30:$H$39,$I$30:$I$39,0) -> 0 | J57: =_xlfn.XLOOKUP(I57,$H$17:$H$26,$I$17:$I$26,0) -> 0 | K57: =_xlfn.XLOOKUP(I57,$H$17:$H$26,$J$17:$J$26,0) -> 0 | M57: =_xlfn.XLOOKUP(L57,$H$30:$H$39,$J$30:$J$39,0) -> 0 | N57: =_xlfn.XLOOKUP(L57,$H$30:$H$39,$K$30:$K$39,0) -> 0
... H63: =_xlfn.XLOOKUP(L63,$H$30:$H$39,$I$30:$I$39,0) -> 0 | J63: =_xlfn.XLOOKUP(I63,$H$17:$H$26,$I$17:$I$26,0) -> 0 | K63: =_xlfn.XLOOKUP(I63,$H$17:$H$26,$J$17:$J$26,0) -> 0 | M63: =_xlfn.XLOOKUP(L63,$H$30:$H$39,$J$30:$J$39,0) -> 0 | N63: =_xlfn.XLOOKUP(L63,$H$30:$H$39,$K$30:$K$39,0) -> 0
H64: Total | O64: =SUM(O44:O63) -> 1010 | P64: =SUM(P44:P63) -> 1010 | Q64: =SUM(Q44:Q63) -> 1010 | R64: =SUM(R44:R63) -> 1010 | S64: =SUM(S44:S63) -> 5050
G66: 8 | H66: Please specify the FTE's (Full-Time-Employment) headcount in the following sections:
H67: P&L Section: | I67: =I12 -> 2026 | J67: =I67+1 -> 2027
H68: COGS | I68: 2 | J68: 3
H69: R&D | I69: 3 | J69: 4
H70: S&M | I70: 4 | J70: 5
...

Sheet Your Company 

Sheet Dashboard
E2: Financial Dashboard
B3: 5-Year revenue, ARR & mix overview
B5: Key metrics — Year 5 (2030)
C7: Total revenue (Yr 5) | F7: Revenue CAGR (Yr1→Yr5) | I7: Software ARR (Yr 5) | L7: Largest customer (Yr 5) | O7: Gross margin (Yr 5)
C8: =G67 -> 194062.5 | F8: =H67 -> 0.24799518 | I8: =G74 -> 194062.5 | L8: =INDEX(B81:B86,MATCH(MAX(G81:G86),G81:G86,0)) -> BULO | O8: ='P&L'!H11 -> 0.5
B63: Supporting data
B65: 1 Total revenue & CAGR | J65: 4 Revenue breakdown — by product
C66: Year 1 (2026) | D66: Year 2 (2027) | E66: Year 3 (2028) | F66: Year 4 (2029) | G66: Year 5 (2030) | H66: CAGR | J66: Product | K66: Year 1 (2026) | L66: Year 2 (2027) | M66: Year 3 (2028) | N66: Year 4 (2029) | O66: Year 5 (2030)
B67: Total Revenue | C67: ='P&L'!D5 -> 80000 | D67: ='P&L'!E5 -> 100000 | E67: ='P&L'!F5 -> 135000 | F67: ='P&L'!G5 -> 168750 | G67: ='P&L'!H5 -> 194062.5 | H67: =IFERROR((G67/C67)^(1/4)-1,0) -> 0.24799518 | J67: =IFERROR(INDEX(_xlfn.ANCHORARRAY($M$115),1),"") -> Big MAC | K67: =IF($J67="",0,SUMIFS(E$116:E$132,$C$116:$C$132,$J67)) -> 40000 | L67: =IF($J67="",0,SUMIFS(F$116:F$132,$C$116:$C$132,$J67)) -> 50000 | M67: =IF($J67="",0,SUMIFS(G$116:G$132,$C$116:$C$132,$J67)) -> 67500 | N67: =IF($J67="",0,SUMIFS(H$116:H$132,$C$116:$C$132,$J67)) -> 84375 | O67: =IF($J67="",0,SUMIFS(I$116:I$132,$C$116:$C$132,$J67)) -> 97031.25 | R67: =TEXT(K67/K$75,"0%") -> 50% | S67: =TEXT(L67/L$75,"0%") -> 50% | T67: =TEXT(M67/M$75,"0%") -> 50% | U67: =TEXT(N67/N$75,"0%") -> 50% | V67: =TEXT(O67/O$75,"0%") -> 50%
B68: CAGR Trajectory | C68: =C67 -> 80000 | D68: =C68*(1+$H$67) -> 99839.615 | E68: =D68*(1+$H$67) -> 124599.36 | F68: =E68*(1+$H$67) -> 155499.4 | G68: =F68*(1+$H$67) -> 194062.5 | J68: =IFERROR(INDEX(_xlfn.ANCHORARRAY($M$115),2),"") -> MCMC | K68: =IF($J68="",0,SUMIFS(E$116:E$132,$C$116:$C$132,$J68)) -> 40000 | L68: =IF($J68="",0,SUMIFS(F$116:F$132,$C$116:$C$132,$J68)) -> 50000 | M68: =IF($J68="",0,SUMIFS(G$116:G$132,$C$116:$C$132,$J68)) -> 67500 | N68: =IF($J68="",0,SUMIFS(H$116:H$132,$C$116:$C$132,$J68)) -> 84375 | O68: =IF($J68="",0,SUMIFS(I$116:I$132,$C$116:$C$132,$J68)) -> 97031.25 | R68: =TEXT(K68/K$75,"0%") -> 50% | S68: =TEXT(L68/L$75,"0%") -> 50% | T68: =TEXT(M68/M$75,"0%") -> 50% | U68: =TEXT(N68/N$75,"0%") -> 50% | V68: =TEXT(O68/O$75,"0%") -> 50%
J69: =IFERROR(INDEX(_xlfn.ANCHORARRAY($M$115),3),"") | K69: =IF($J69="",0,SUMIFS(E$116:E$132,$C$116:$C$132,$J69)) -> 0 | L69: =IF($J69="",0,SUMIFS(F$116:F$132,$C$116:$C$132,$J69)) -> 0 | M69: =IF($J69="",0,SUMIFS(G$116:G$132,$C$116:$C$132,$J69)) -> 0 | N69: =IF($J69="",0,SUMIFS(H$116:H$132,$C$116:$C$132,$J69)) -> 0 | O69: =IF($J69="",0,SUMIFS(I$116:I$132,$C$116:$C$132,$J69)) -> 0 | R69: =TEXT(K69/K$75,"0%") -> 0% | S69: =TEXT(L69/L$75,"0%") -> 0% | T69: =TEXT(M69/M$75,"0%") -> 0% | U69: =TEXT(N69/N$75,"0%") -> 0% | V69: =TEXT(O69/O$75,"0%") -> 0%
J70: =IFERROR(INDEX(_xlfn.ANCHORARRAY($M$115),4),"") | K70: =IF($J70="",0,SUMIFS(E$116:E$132,$C$116:$C$132,$J70)) -> 0 | L70: =IF($J70="",0,SUMIFS(F$116:F$132,$C$116:$C$132,$J70)) -> 0 | M70: =IF($J70="",0,SUMIFS(G$116:G$132,$C$116:$C$132,$J70)) -> 0 | N70: =IF($J70="",0,SUMIFS(H$116:H$132,$C$116:$C$132,$J70)) -> 0 | O70: =IF($J70="",0,SUMIFS(I$116:I$132,$C$116:$C$132,$J70)) -> 0 | R70: =TEXT(K70/K$75,"0%") -> 0% | S70: =TEXT(L70/L$75,"0%") -> 0% | T70: =TEXT(M70/M$75,"0%") -> 0% | U70: =TEXT(N70/N$75,"0%") -> 0% | V70: =TEXT(O70/O$75,"0%") -> 0%
J71: =IFERROR(INDEX(_xlfn.ANCHORARRAY($M$115),5),"") | K71: =IF($J71="",0,SUMIFS(E$116:E$132,$C$116:$C$132,$J71)) -> 0 | L71: =IF($J71="",0,SUMIFS(F$116:F$132,$C$116:$C$132,$J71)) -> 0 | M71: =IF($J71="",0,SUMIFS(G$116:G$132,$C$116:$C$132,$J71)) -> 0 | N71: =IF($J71="",0,SUMIFS(H$116:H$132,$C$116:$C$132,$J71)) -> 0 | O71: =IF($J71="",0,SUMIFS(I$116:I$132,$C$116:$C$132,$J71)) -> 0 | R71: =TEXT(K71/K$75,"0%") -> 0% | S71: =TEXT(L71/L$75,"0%") -> 0% | T71: =TEXT(M71/M$75,"0%") -> 0% | U71: =TEXT(N71/N$75,"0%") -> 0% | V71: =TEXT(O71/O$75,"0%") -> 0%
B72: 2 Software ARR | J72: =IFERROR(INDEX(_xlfn.ANCHORARRAY($M$115),6),"") | K72: =IF($J72="",0,SUMIFS(E$116:E$132,$C$116:$C$132,$J72)) -> 0 | L72: =IF($J72="",0,SUMIFS(F$116:F$132,$C$116:$C$132,$J72)) -> 0 | M72: =IF($J72="",0,SUMIFS(G$116:G$132,$C$116:$C$132,$J72)) -> 0 | N72: =IF($J72="",0,SUMIFS(H$116:H$132,$C$116:$C$132,$J72)) -> 0 | O72: =IF($J72="",0,SUMIFS(I$116:I$132,$C$116:$C$132,$J72)) -> 0 | R72: =TEXT(K72/K$75,"0%") -> 0% | S72: =TEXT(L72/L$75,"0%") -> 0% | T72: =TEXT(M72/M$75,"0%") -> 0% | U72: =TEXT(N72/N$75,"0%") -> 0% | V72: =TEXT(O72/O$75,"0%") -> 0%
C73: Year 1 (2026) | D73: Year 2 (2027) | E73: Year 3 (2028) | F73: Year 4 (2029) | G73: Year 5 (2030) | H73: CAGR | J73: =IFERROR(INDEX(_xlfn.ANCHORARRAY($M$115),7),"") | K73: =IF($J73="",0,SUMIFS(E$116:E$132,$C$116:$C$132,$J73)) -> 0 | L73: =IF($J73="",0,SUMIFS(F$116:F$132,$C$116:$C$132,$J73)) -> 0 | M73: =IF($J73="",0,SUMIFS(G$116:G$132,$C$116:$C$132,$J73)) -> 0 | N73: =IF($J73="",0,SUMIFS(H$116:H$132,$C$116:$C$132,$J73)) -> 0 | O73: =IF($J73="",0,SUMIFS(I$116:I$132,$C$116:$C$132,$J73)) -> 0 | R73: =TEXT(K73/K$75,"0%") -> 0% | S73: =TEXT(L73/L$75,"0%") -> 0% | T73: =TEXT(M73/M$75,"0%") -> 0% | U73: =TEXT(N73/N$75,"0%") -> 0% | V73: =TEXT(O73/O$75,"0%") -> 0%
B74: Software ARR | C74: ='Rev. Build'!J54*4 -> 80000 | D74: ='Rev. Build'!O54*4 -> 100000 | E74: ='Rev. Build'!T54*4 -> 135000 | F74: ='Rev. Build'!Y54*4 -> 168750 | G74: ='Rev. Build'!AD54*4 -> 194062.5 | H74: =IFERROR((G74/C74)^(1/4)-1,0) -> 0.24799518 | J74: =IFERROR(INDEX(_xlfn.ANCHORARRAY($M$115),8),"") | K74: =IF($J74="",0,SUMIFS(E$116:E$132,$C$116:$C$132,$J74)) -> 0 | L74: =IF($J74="",0,SUMIFS(F$116:F$132,$C$116:$C$132,$J74)) -> 0 | M74: =IF($J74="",0,SUMIFS(G$116:G$132,$C$116:$C$132,$J74)) -> 0 | N74: =IF($J74="",0,SUMIFS(H$116:H$132,$C$116:$C$132,$J74)) -> 0 | O74: =IF($J74="",0,SUMIFS(I$116:I$132,$C$116:$C$132,$J74)) -> 0 | R74: =TEXT(K74/K$75,"0%") -> 0% | S74: =TEXT(L74/L$75,"0%") -> 0% | T74: =TEXT(M74/M$75,"0%") -> 0% | U74: =TEXT(N74/N$75,"0%") -> 0% | V74: =TEXT(O74/O$75,"0%") -> 0%
B75: Software CAGR Trajectory | C75: =C74 -> 80000 | D75: =C75*(1+$H$74) -> 99839.615 | E75: =D75*(1+$H$74) -> 124599.36 | F75: =E75*(1+$H$74) -> 155499.4 | G75: =F75*(1+$H$74) -> 194062.5 | J75: Total | K75: =SUM(K67:K74) -> 80000 | L75: =SUM(L67:L74) -> 100000 | M75: =SUM(M67:M74) -> 135000 | N75: =SUM(N67:N74) -> 168750 | O75: =SUM(O67:O74) -> 194062.5
J77: % Contribution
J78: =$J$67 -> Big MAC | K78: =IFERROR(K67/K$75,0) -> 0.5 | L78: =IFERROR(L67/L$75,0) -> 0.5 | M78: =IFERROR(M67/M$75,0) -> 0.5 | N78: =IFERROR(N67/N$75,0) -> 0.5 | O78: =IFERROR(O67/O$75,0) -> 0.5
B79: 3 Revenue breakdown — by customer | J79: =$J$68 -> MCMC | K79: =IFERROR(K68/K$75,0) -> 0.5 | L79: =IFERROR(L68/L$75,0) -> 0.5 | M79: =IFERROR(M68/M$75,0) -> 0.5 | N79: =IFERROR(N68/N$75,0) -> 0.5 | O79: =IFERROR(O68/O$75,0) -> 0.5
B80: Customer | C80: Year 1 (2026) | D80: Year 2 (2027) | E80: Year 3 (2028) | F80: Year 4 (2029) | G80: Year 5 (2030) | J80: =$J$69 | K80: =IFERROR(K69/K$75,0) -> 0 | L80: =IFERROR(L69/L$75,0) -> 0 | M80: =IFERROR(M69/M$75,0) -> 0 | N80: =IFERROR(N69/N$75,0) -> 0 | O80: =IFERROR(O69/O$75,0) -> 0
B81: =IFERROR(INDEX(_xlfn.ANCHORARRAY($L$115),1),"") -> Hungry AF | C81: =IF($B81="",0,SUMIFS(E$116:E$132,$B$116:$B$132,$B81)) -> 40000 | D81: =IF($B81="",0,SUMIFS(F$116:F$132,$B$116:$B$132,$B81)) -> 50000 | E81: =IF($B81="",0,SUMIFS(G$116:G$132,$B$116:$B$132,$B81)) -> 67500 | F81: =IF($B81="",0,SUMIFS(H$116:H$132,$B$116:$B$132,$B81)) -> 84375 | G81: =IF($B81="",0,SUMIFS(I$116:I$132,$B$116:$B$132,$B81)) -> 97031.25 | J81: =$J$70 | K81: =IFERROR(K70/K$75,0) -> 0 | L81: =IFERROR(L70/L$75,0) -> 0 | M81: =IFERROR(M70/M$75,0) -> 0 | N81: =IFERROR(N70/N$75,0) -> 0 | O81: =IFERROR(O70/O$75,0) -> 0 | R81: =TEXT(C81/C$87,"0%") -> 50% | S81: =TEXT(D81/D$87,"0%") -> 50% | T81: =TEXT(E81/E$87,"0%") -> 50% | U81: =TEXT(F81/F$87,"0%") -> 50% | V81: =TEXT(G81/G$87,"0%") -> 50%
B82: =IFERROR(INDEX(_xlfn.ANCHORARRAY($L$115),2),"") -> BULO | C82: =IF($B82="",0,SUMIFS(E$116:E$132,$B$116:$B$132,$B82)) -> 40000 | D82: =IF($B82="",0,SUMIFS(F$116:F$132,$B$116:$B$132,$B82)) -> 50000 | E82: =IF($B82="",0,SUMIFS(G$116:G$132,$B$116:$B$132,$B82)) -> 67500 | F82: =IF($B82="",0,SUMIFS(H$116:H$132,$B$116:$B$132,$B82)) -> 84375 | G82: =IF($B82="",0,SUMIFS(I$116:I$132,$B$116:$B$132,$B82)) -> 97031.25 | J82: =$J$71 | K82: =IFERROR(K71/K$75,0) -> 0 | L82: =IFERROR(L71/L$75,0) -> 0 | M82: =IFERROR(M71/M$75,0) -> 0 | N82: =IFERROR(N71/N$75,0) -> 0 | O82: =IFERROR(O71/O$75,0) -> 0 | R82: =TEXT(C82/C$87,"0%") -> 50% | S82: =TEXT(D82/D$87,"0%") -> 50% | T82: =TEXT(E82/E$87,"0%") -> 50% | U82: =TEXT(F82/F$87,"0%") -> 50% | V82: =TEXT(G82/G$87,"0%") -> 50%
B83: =IFERROR(INDEX(_xlfn.ANCHORARRAY($L$115),3),"") | C83: =IF($B83="",0,SUMIFS(E$116:E$132,$B$116:$B$132,$B83)) -> 0 | D83: =IF($B83="",0,SUMIFS(F$116:F$132,$B$116:$B$132,$B83)) -> 0 | E83: =IF($B83="",0,SUMIFS(G$116:G$132,$B$116:$B$132,$B83)) -> 0 | F83: =IF($B83="",0,SUMIFS(H$116:H$132,$B$116:$B$132,$B83)) -> 0 | G83: =IF($B83="",0,SUMIFS(I$116:I$132,$B$116:$B$132,$B83)) -> 0 | J83: =$J$72 | K83: =IFERROR(K72/K$75,0) -> 0 | L83: =IFERROR(L72/L$75,0) -> 0 | M83: =IFERROR(M72/M$75,0) -> 0 | N83: =IFERROR(N72/N$75,0) -> 0 | O83: =IFERROR(O72/O$75,0) -> 0 | R83: =TEXT(C83/C$87,"0%") -> 0% | S83: =TEXT(D83/D$87,"0%") -> 0% | T83: =TEXT(E83/E$87,"0%") -> 0% | U83: =TEXT(F83/F$87,"0%") -> 0% | V83: =TEXT(G83/G$87,"0%") -> 0%
B84: =IFERROR(INDEX(_xlfn.ANCHORARRAY($L$115),4),"") | C84: =IF($B84="",0,SUMIFS(E$116:E$132,$B$116:$B$132,$B84)) -> 0 | D84: =IF($B84="",0,SUMIFS(F$116:F$132,$B$116:$B$132,$B84)) -> 0 | E84: =IF($B84="",0,SUMIFS(G$116:G$132,$B$116:$B$132,$B84)) -> 0 | F84: =IF($B84="",0,SUMIFS(H$116:H$132,$B$116:$B$132,$B84)) -> 0 | G84: =IF($B84="",0,SUMIFS(I$116:I$132,$B$116:$B$132,$B84)) -> 0 | J84: =$J$73 | K84: =IFERROR(K73/K$75,0) -> 0 | L84: =IFERROR(L73/L$75,0) -> 0 | M84: =IFERROR(M73/M$75,0) -> 0 | N84: =IFERROR(N73/N$75,0) -> 0 | O84: =IFERROR(O73/O$75,0) -> 0 | R84: =TEXT(C84/C$87,"0%") -> 0% | S84: =TEXT(D84/D$87,"0%") -> 0% | T84: =TEXT(E84/E$87,"0%") -> 0% | U84: =TEXT(F84/F$87,"0%") -> 0% | V84: =TEXT(G84/G$87,"0%") -> 0%
B85: =IFERROR(INDEX(_xlfn.ANCHORARRAY($L$115),5),"") | C85: =IF($B85="",0,SUMIFS(E$116:E$132,$B$116:$B$132,$B85)) -> 0 | D85: =IF($B85="",0,SUMIFS(F$116:F$132,$B$116:$B$132,$B85)) -> 0 | E85: =IF($B85="",0,SUMIFS(G$116:G$132,$B$116:$B$132,$B85)) -> 0 | F85: =IF($B85="",0,SUMIFS(H$116:H$132,$B$116:$B$132,$B85)) -> 0 | G85: =IF($B85="",0,SUMIFS(I$116:I$132,$B$116:$B$132,$B85)) -> 0 | J85: =$J$74 | K85: =IFERROR(K74/K$75,0) -> 0 | L85: =IFERROR(L74/L$75,0) -> 0 | M85: =IFERROR(M74/M$75,0) -> 0 | N85: =IFERROR(N74/N$75,0) -> 0 | O85: =IFERROR(O74/O$75,0) -> 0 | R85: =TEXT(C85/C$87,"0%") -> 0% | S85: =TEXT(D85/D$87,"0%") -> 0% | T85: =TEXT(E85/E$87,"0%") -> 0% | U85: =TEXT(F85/F$87,"0%") -> 0% | V85: =TEXT(G85/G$87,"0%") -> 0%
B86: =IFERROR(INDEX(_xlfn.ANCHORARRAY($L$115),6),"") | C86: =IF($B86="",0,SUMIFS(E$116:E$132,$B$116:$B$132,$B86)) -> 0 | D86: =IF($B86="",0,SUMIFS(F$116:F$132,$B$116:$B$132,$B86)) -> 0 | E86: =IF($B86="",0,SUMIFS(G$116:G$132,$B$116:$B$132,$B86)) -> 0 | F86: =IF($B86="",0,SUMIFS(H$116:H$132,$B$116:$B$132,$B86)) -> 0 | G86: =IF($B86="",0,SUMIFS(I$116:I$132,$B$116:$B$132,$B86)) -> 0 | R86: =TEXT(C86/C$87,"0%") -> 0% | S86: =TEXT(D86/D$87,"0%") -> 0% | T86: =TEXT(E86/E$87,"0%") -> 0% | U86: =TEXT(F86/F$87,"0%") -> 0% | V86: =TEXT(G86/G$87,"0%") -> 0%
B87: Total | C87: =SUM(C81:C86) -> 80000 | D87: =SUM(D81:D86) -> 100000 | E87: =SUM(E81:E86) -> 135000 | F87: =SUM(F81:F86) -> 168750 | G87: =SUM(G81:G86) -> 194062.5
J89: 5 Revenue breakdown — by territory
J90: Territory | K90: Year 1 (2026) | L90: Year 2 (2027) | M90: Year 3 (2028) | N90: Year 4 (2029) | O90: Year 5 (2030)
J91: =IFERROR(INDEX(_xlfn.ANCHORARRAY($N$115),1),"") -> US | K91: =IF($J91="",0,SUMIFS(E$116:E$132,$D$116:$D$132,$J91)) -> 40000 | L91: =IF($J91="",0,SUMIFS(F$116:F$132,$D$116:$D$132,$J91)) -> 50000 | M91: =IF($J91="",0,SUMIFS(G$116:G$132,$D$116:$D$132,$J91)) -> 67500 | N91: =IF($J91="",0,SUMIFS(H$116:H$132,$D$116:$D$132,$J91)) -> 84375 | O91: =IF($J91="",0,SUMIFS(I$116:I$132,$D$116:$D$132,$J91)) -> 97031.25 | R91: =TEXT(K91/K$94,"0%") -> 50% | S91: =TEXT(L91/L$94,"0%") -> 50% | T91: =TEXT(M91/M$94,"0%") -> 50% | U91: =TEXT(N91/N$94,"0%") -> 50% | V91: =TEXT(O91/O$94,"0%") -> 50%
J92: =IFERROR(INDEX(_xlfn.ANCHORARRAY($N$115),2),"") -> EU | K92: =IF($J92="",0,SUMIFS(E$116:E$132,$D$116:$D$132,$J92)) -> 40000 | L92: =IF($J92="",0,SUMIFS(F$116:F$132,$D$116:$D$132,$J92)) -> 50000 | M92: =IF($J92="",0,SUMIFS(G$116:G$132,$D$116:$D$132,$J92)) -> 67500 | N92: =IF($J92="",0,SUMIFS(H$116:H$132,$D$116:$D$132,$J92)) -> 84375 | O92: =IF($J92="",0,SUMIFS(I$116:I$132,$D$116:$D$132,$J92)) -> 97031.25 | R92: =TEXT(K92/K$94,"0%") -> 50% | S92: =TEXT(L92/L$94,"0%") -> 50% | T92: =TEXT(M92/M$94,"0%") -> 50% | U92: =TEXT(N92/N$94,"0%") -> 50% | V92: =TEXT(O92/O$94,"0%") -> 50%
J93: =IFERROR(INDEX(_xlfn.ANCHORARRAY($N$115),3),"") | K93: =IF($J93="",0,SUMIFS(E$116:E$132,$D$116:$D$132,$J93)) -> 0 | L93: =IF($J93="",0,SUMIFS(F$116:F$132,$D$116:$D$132,$J93)) -> 0 | M93: =IF($J93="",0,SUMIFS(G$116:G$132,$D$116:$D$132,$J93)) -> 0 | N93: =IF($J93="",0,SUMIFS(H$116:H$132,$D$116:$D$132,$J93)) -> 0 | O93: =IF($J93="",0,SUMIFS(I$116:I$132,$D$116:$D$132,$J93)) -> 0 | R93: =TEXT(K93/K$94,"0%") -> 0% | S93: =TEXT(L93/L$94,"0%") -> 0% | T93: =TEXT(M93/M$94,"0%") -> 0% | U93: =TEXT(N93/N$94,"0%") -> 0% | V93: =TEXT(O93/O$94,"0%") -> 0%
J94: Total | K94: =SUM(K91:K93) -> 80000 | L94: =SUM(L91:L93) -> 100000 | M94: =SUM(M91:M93) -> 135000 | N94: =SUM(N91:N93) -> 168750 | O94: =SUM(O91:O93) -> 194062.5
J96: % Contribution
B97: P&L | J97: =$J$91 -> US | K97: =IFERROR(K91/K$94,0) -> 0.5 | L97: =IFERROR(L91/L$94,0) -> 0.5 | M97: =IFERROR(M91/M$94,0) -> 0.5 | N97: =IFERROR(N91/N$94,0) -> 0.5 | O97: =IFERROR(O91/O$94,0) -> 0.5
B98: ='P&L'!C4 -> 2025 | C98: ='P&L'!D4 -> 2026 | D98: ='P&L'!E4 -> 2027 | E98: ='P&L'!F4 -> 2028 | F98: ='P&L'!G4 -> 2029 | G98: ='P&L'!H4 -> 2030 | J98: =$J$92 -> EU | K98: =IFERROR(K92/K$94,0) -> 0.5 | L98: =IFERROR(L92/L$94,0) -> 0.5 | M98: =IFERROR(M92/M$94,0) -> 0.5 | N98: =IFERROR(N92/N$94,0) -> 0.5 | O98: =IFERROR(O92/O$94,0) -> 0.5
A99: ='P&L'!B5 -> Revenues | B99: ='P&L'!C5 -> 10000 | C99: ='P&L'!D5 -> 80000 | D99: ='P&L'!E5 -> 100000 | E99: ='P&L'!F5 -> 135000 | F99: ='P&L'!G5 -> 168750 | G99: ='P&L'!H5 -> 194062.5 | J99: =$J$93 | K99: =IFERROR(K93/K$94,0) -> 0 | L99: =IFERROR(L93/L$94,0) -> 0 | M99: =IFERROR(M93/M$94,0) -> 0 | N99: =IFERROR(N93/N$94,0) -> 0 | O99: =IFERROR(O93/O$94,0) -> 0
A100: ='P&L'!B8 -> COGS | B100: ='P&L'!C8 -> 5000 | C100: ='P&L'!D8 -> 40000 | D100: ='P&L'!E8 -> 50000 | E100: ='P&L'!F8 -> 67500 | F100: ='P&L'!G8 -> 84375 | G100: ='P&L'!H8 -> 97031.25
A101: ='P&L'!B10 -> Gross Profit | B101: ='P&L'!C10 -> 5000 | C101: ='P&L'!D10 -> 40000 | D101: ='P&L'!E10 -> 50000 | E101: ='P&L'!F10 -> 67500 | F101: ='P&L'!G10 -> 84375 | G101: ='P&L'!H10 -> 97031.25
...

Sheet Qualitative Assumptions
G1: Qualitative Assumptions:
G2: 1
G3: 2
G4: 3
G5: 4
G6: 5
G7: 6
G8: 7
G9: 8
G10: 9
G11: 10
G12: 11
G13: 12
... G20: 19
G22: Assumptions Metrics | I22: Price Increase | J22: Price Increase | K22: Price Increase | L22: Price Increase
I23: 0.02 | J23: 0 | K23: 0 | L23: 0.02
G24: Unit Sale Price: | H24: 2026 | I24: 2027 | J24: 2028 | K24: 2029 | L24: 2030
G25: Customer A- Product A | H25: 160000 | I25: =H25*(1+I$23) -> 163200 | J25: =I25*(1+J$23) -> 163200 | K25: =J25*(1+K$23) -> 163200 | L25: =K25*(1+L$23) -> 166464
G26: Customer A- Product B | H26: 120000 | I26: =H26*(1+I$23) -> 122400 | J26: =I26*(1+J$23) -> 122400 | K26: =J26*(1+K$23) -> 122400 | L26: =K26*(1+L$23) -> 124848
G27: Customer A- Product C | H27: 100000 | I27: =H27*(1+I$23) -> 102000 | J27: =I27*(1+J$23) -> 102000 | K27: =J27*(1+K$23) -> 102000 | L27: =K27*(1+L$23) -> 104040
G28: Customer B- Product A | H28: 130000 | I28: =H28*(1+I$23) -> 132600 | J28: =I28*(1+J$23) -> 132600 | K28: =J28*(1+K$23) -> 132600 | L28: =K28*(1+L$23) -> 135252
G29: Customer B- Product B | H29: 110000 | I29: =H29*(1+I$23) -> 112200 | J29: =I29*(1+J$23) -> 112200 | K29: =J29*(1+K$23) -> 112200 | L29: =K29*(1+L$23) -> 114444
G30: Customer B- Product C | H30: 90000 | I30: =H30*(1+I$23) -> 91800 | J30: =I30*(1+J$23) -> 91800 | K30: =J30*(1+K$23) -> 91800 | L30: =K30*(1+L$23) -> 93636
G31: Customer C- Product A | H31: 120000 | I31: =H31*(1+I$23) -> 122400 | J31: =I31*(1+J$23) -> 122400 | K31: =J31*(1+K$23) -> 122400 | L31: =K31*(1+L$23) -> 124848
G32: Customer C- Product B | H32: 100000 | I32: =H32*(1+I$23) -> 102000 | J32: =I32*(1+J$23) -> 102000 | K32: =J32*(1+K$23) -> 102000 | L32: =K32*(1+L$23) -> 104040
G33: Customer C- Product C | H33: 85000 | I33: =H33*(1+I$23) -> 86700 | J33: =I33*(1+J$23) -> 86700 | K33: =J33*(1+K$23) -> 86700 | L33: =K33*(1+L$23) -> 88434
I35: Cost Increase | J35: Cost Increase | K35: Cost Increase | L35: Cost Increase
I36: 0.02 | J36: 0 | K36: 0 | L36: 0.02
G37: Unit Cost: | H37: 2026 | I37: 2027 | J37: 2028 | K37: 2029 | L37: 2030
G38: Product A | H38: 87000 | I38: =H38*(1+I$36) -> 88740 | J38: =I38*(1+J$36) -> 88740 | K38: =J38*(1+K$36) -> 88740 | L38: =K38*(1+L$36) -> 90514.8
G39: Product B | H39: 67000 | I39: =H39*(1+I$36) -> 68340 | J39: =I39*(1+J$36) -> 68340 | K39: =J39*(1+K$36) -> 68340 | L39: =K39*(1+L$36) -> 69706.8
G40: Product C | H40: 67000 | I40: =H40*(1+I$36) -> 68340 | J40: =I40*(1+J$36) -> 68340 | K40: =J40*(1+K$36) -> 68340 | L40: =K40*(1+L$36) -> 69706.8

Sheet P&L
C4: 2025 | D4: 2026 | E4: 2027 | F4: 2028 | G4: 2029 | H4: 2030 | I4: CAGR
B5: Revenues | C5: 10000 | D5: ='Rev. Build'!K54 -> 80000 | E5: ='Rev. Build'!P54 -> 100000 | F5: ='Rev. Build'!U54 -> 135000 | G5: ='Rev. Build'!Z54 -> 168750 | H5: ='Rev. Build'!AE54 -> 194062.5 | I5: =(H5/C5)^(1/5)-1 -> 0.8096239
B6: % Growth | D6: =D5/C5-1 -> 7 | E6: =E5/D5-1 -> 0.25 | F6: =F5/E5-1 -> 0.35 | G6: =G5/F5-1 -> 0.25 | H6: =H5/G5-1 -> 0.15
B8: COGS | C8: 5000 | D8: =COGS!K51 -> 40000 | E8: =COGS!P51 -> 50000 | F8: =COGS!U51 -> 67500 | G8: =COGS!Z51 -> 84375 | H8: =COGS!AE51 -> 97031.25
B10: Gross Profit | C10: =C5-C8 -> 5000 | D10: =D5-D8 -> 40000 | E10: =E5-E8 -> 50000 | F10: =F5-F8 -> 67500 | G10: =G5-G8 -> 84375 | H10: =H5-H8 -> 97031.25
B11: % Margin | C11: =C10/C$5 -> 0.5 | D11: =D10/D$5 -> 0.5 | E11: =E10/E$5 -> 0.5 | F11: =F10/F$5 -> 0.5 | G11: =G10/G$5 -> 0.5 | H11: =H10/H$5 -> 0.5
B13: S&M | C13: 2000 | D13: =OPEX!K33 -> 400000 | E13: =OPEX!P33 -> 500000 | F13: =OPEX!U33 -> 725000 | G13: =OPEX!Z33 -> 957000 | H13: =OPEX!AE33 -> 1167540
B14: % Margin | C14: =-C13/C$5 -> -0.2 | D14: =-D13/D$5 -> -5 | E14: =-E13/E$5 -> -5 | F14: =-F13/F$5 -> -5.3703704 | G14: =-G13/G$5 -> -5.6711111 | H14: =-H13/H$5 -> -6.0163092
B15: G&A | D15: =OPEX!K48 -> 500000 | E15: =OPEX!P48 -> 600000 | F15: =OPEX!U48 -> 828000 | G15: =OPEX!Z48 -> 1101240 | H15: =OPEX!AE48 -> 1409587.2
B16: % Margin | C16: =-C15/C$5 -> 0 | D16: =-D15/D$5 -> -6.25 | E16: =-E15/E$5 -> -6 | F16: =-F15/F$5 -> -6.1333333 | G16: =-G15/G$5 -> -6.5258667 | H16: =-H15/H$5 -> -7.2635733
B17: R&D | D17: =OPEX!K18 -> 300000 | E17: =OPEX!P18 -> 400000 | F17: =OPEX!U18 -> 532000 | G17: =OPEX!Z18 -> 680960 | H17: =OPEX!AE18 -> 817152
B18: % Margin | C18: =-C17/C$5 -> 0 | D18: =-D17/D$5 -> -3.75 | E18: =-E17/E$5 -> -4 | F18: =-F17/F$5 -> -3.9407407 | G18: =-G17/G$5 -> -4.0353185 | H18: =-H17/H$5 -> -4.2107671
B20: Total OPEX | C20: =C17+C15+C13 -> 2000 | D20: =D17+D15+D13 -> 1200000 | E20: =E17+E15+E13 -> 1500000 | F20: =F17+F15+F13 -> 2085000 | G20: =G17+G15+G13 -> 2739200 | H20: =H17+H15+H13 -> 3394279.2
B21: OPEX % | C21: =-(C13+C15+C17)/C$5 -> -0.2 | D21: =-(D13+D15+D17)/D$5 -> -15 | E21: =-(E13+E15+E17)/E$5 -> -15 | F21: =-(F13+F15+F17)/F$5 -> -15.444444 | G21: =-(G13+G15+G17)/G$5 -> -16.232296 | H21: =-(H13+H15+H17)/H$5 -> -17.49065
B23: Adj. EBITDA | C23: =C10-C20 -> 3000 | D23: =D10-D20 -> -1160000 | E23: =E10-E20 -> -1450000 | F23: =F10-F20 -> -2017500 | G23: =G10-G20 -> -2654825 | H23: =H10-H20 -> -3297248
B24: % Margin | C24: =C23/C5 -> 0.3 | D24: =D23/D5 -> -14.5 | E24: =E23/E5 -> -14.5 | F24: =F23/F5 -> -14.944444 | G24: =G23/G5 -> -15.732296 | H24: =H23/H5 -> -16.99065
B26: WC rate from rev. | C26: -0.1 | D26: -0.1 | E26: -0.1 | F26: -0.1 | G26: -0.1 | H26: -0.1
B27: WC | C27: =C26*C5 -> -1000
B28: Capex
B29: Financing, net
B30: Tax
B31: Free Cash Flow | C31: =C23+SUM(C27:C30) -> 2000 | D31: =D23+SUM(D27:D30) -> -1160000 | E31: =E23+SUM(E27:E30) -> -1450000 | F31: =F23+SUM(F27:F30) -> -2017500 | G31: =G23+SUM(G27:G30) -> -2654825 | H31: =H23+SUM(H27:H30) -> -3297248

Sheet Rev. Build
A4: ='Customer''s Questionnaire'!H8 -> Company's sector | B4: ='Customer''s Questionnaire'!I8 -> Food-Tech / Ag-Tech
A5: ='Customer''s Questionnaire'!H9 -> Upcoming Round | B5: ='Customer''s Questionnaire'!I9 -> Round C | G5: =B5 -> Round C | L5: =_xlfn.XLOOKUP($B$4&L$6,Benchmark_Table!$F:$F,Benchmark_Table!$B:$B,G$5) -> Series C | Q5: =_xlfn.XLOOKUP($B$4&Q$6,Benchmark_Table!$F:$F,Benchmark_Table!$B:$B,L$5) -> Series C | V5: =_xlfn.XLOOKUP($B$4&V$6,Benchmark_Table!$F:$F,Benchmark_Table!$B:$B,Q$5) -> Series D/E | AA5: =_xlfn.XLOOKUP($B$4&AA$6,Benchmark_Table!$F:$F,Benchmark_Table!$B:$B,V$5) -> Pre-IPO | AF5: =_xlfn.XLOOKUP($B$4&AF$6,Benchmark_Table!$F:$F,Benchmark_Table!$B:$B,AA$5) -> Pre-IPO | AK5: =_xlfn.XLOOKUP($B$4&AK$6,Benchmark_Table!$F:$F,Benchmark_Table!$B:$B,AF$5) -> Pre-IPO | AP5: =_xlfn.XLOOKUP($B$4&AP$6,Benchmark_Table!$F:$F,Benchmark_Table!$B:$B,AK$5) -> Pre-IPO | AU5: =_xlfn.XLOOKUP($B$4&AU$6,Benchmark_Table!$F:$F,Benchmark_Table!$B:$B,AP$5) -> Pre-IPO | AZ5: =_xlfn.XLOOKUP($B$4&AZ$6,Benchmark_Table!$F:$F,Benchmark_Table!$B:$B,AU$5) -> Pre-IPO | BE5: =_xlfn.XLOOKUP($B$4&BE$6,Benchmark_Table!$F:$F,Benchmark_Table!$B:$B,AZ$5) -> Pre-IPO | BJ5: =_xlfn.XLOOKUP($B$4&BJ$6,Benchmark_Table!$F:$F,Benchmark_Table!$B:$B,BE$5) -> Pre-IPO
A6: ='Customer''s Questionnaire'!H11 -> Avg_Years_Since_Founding | B6: ='Customer''s Questionnaire'!I11 -> 7 | G6: =B6 -> 7 | L6: =G6+1 -> 8 | Q6: =L6+1 -> 9 | V6: =Q6+1 -> 10 | AA6: =V6+1 -> 11 | AF6: =AA6+1 -> 12 | AK6: =AF6+1 -> 13 | AP6: =AK6+1 -> 14 | AU6: =AP6+1 -> 15 | AZ6: =AU6+1 -> 16 | BE6: =AZ6+1 -> 17 | BJ6: =BE6+1 -> 18
A7: Growth Benchmark | B7: =IF(OR('Customer''s Questionnaire'!J10="Too Low",'Customer''s Questionnaire'!J10="Low"),Benchmark_Table!AY1,IF(OR('Customer''s Questionnaire'!J10="Too High",'Customer''s Questionnaire'!J10="High"),Benchmark_Table!BA1,Benchmark_Table!AZ1)) -> Revenue_Growth_High | G7: =_xlfn.IFNA(INDEX(Benchmark_Table!$H$2:$BL$136,MATCH('Rev. Build'!$B$4&'Rev. Build'!G$5&G$6,Benchmark_Table!$G$2:$G$136,0),MATCH('Rev. Build'!$B$7,Benchmark_Table!$H$1:$BL$1,0)),0%) -> 0 | L7: =_xlfn.IFNA(INDEX(Benchmark_Table!$H$2:$BL$136,MATCH('Rev. Build'!$B$4&'Rev. Build'!L$5&L$6,Benchmark_Table!$G$2:$G$136,0),MATCH('Rev. Build'!$B$7,Benchmark_Table!$H$1:$BL$1,0)),G$7) -> 0.35 | Q7: =_xlfn.IFNA(INDEX(Benchmark_Table!$H$2:$BL$136,MATCH('Rev. Build'!$B$4&'Rev. Build'!Q$5&Q$6,Benchmark_Table!$G$2:$G$136,0),MATCH('Rev. Build'!$B$7,Benchmark_Table!$H$1:$BL$1,0)),L$7) -> 0.35 | V7: =_xlfn.IFNA(INDEX(Benchmark_Table!$H$2:$BL$136,MATCH('Rev. Build'!$B$4&'Rev. Build'!V$5&V$6,Benchmark_Table!$G$2:$G$136,0),MATCH('Rev. Build'!$B$7,Benchmark_Table!$H$1:$BL$1,0)),Q$7) -> 0.25 | AA7: =_xlfn.IFNA(INDEX(Benchmark_Table!$H$2:$BL$136,MATCH('Rev. Build'!$B$4&'Rev. Build'!AA$5&AA$6,Benchmark_Table!$G$2:$G$136,0),MATCH('Rev. Build'!$B$7,Benchmark_Table!$H$1:$BL$1,0)),V$7) -> 0.15 | AF7: =_xlfn.IFNA(INDEX(Benchmark_Table!$H$2:$BL$136,MATCH('Rev. Build'!$B$4&'Rev. Build'!AF$5&AF$6,Benchmark_Table!$G$2:$G$136,0),MATCH('Rev. Build'!$B$7,Benchmark_Table!$H$1:$BL$1,0)),AA$7) -> 0.15 | AK7: =_xlfn.IFNA(INDEX(Benchmark_Table!$H$2:$BL$136,MATCH('Rev. Build'!$B$4&'Rev. Build'!AK$5&AK$6,Benchmark_Table!$G$2:$G$136,0),MATCH('Rev. Build'!$B$7,Benchmark_Table!$H$1:$BL$1,0)),AF$7) -> 0.15 | AP7: =_xlfn.IFNA(INDEX(Benchmark_Table!$H$2:$BL$136,MATCH('Rev. Build'!$B$4&'Rev. Build'!AP$5&AP$6,Benchmark_Table!$G$2:$G$136,0),MATCH('Rev. Build'!$B$7,Benchmark_Table!$H$1:$BL$1,0)),AK$7) -> 0.15 | AU7: =_xlfn.IFNA(INDEX(Benchmark_Table!$H$2:$BL$136,MATCH('Rev. Build'!$B$4&'Rev. Build'!AU$5&AU$6,Benchmark_Table!$G$2:$G$136,0),MATCH('Rev. Build'!$B$7,Benchmark_Table!$H$1:$BL$1,0)),AP$7) -> 0.15 | AZ7: =_xlfn.IFNA(INDEX(Benchmark_Table!$H$2:$BL$136,MATCH('Rev. Build'!$B$4&'Rev. Build'!AZ$5&AZ$6,Benchmark_Table!$G$2:$G$136,0),MATCH('Rev. Build'!$B$7,Benchmark_Table!$H$1:$BL$1,0)),AU$7) -> 0.15 | BE7: =_xlfn.IFNA(INDEX(Benchmark_Table!$H$2:$BL$136,MATCH('Rev. Build'!$B$4&'Rev. Build'!BE$5&BE$6,Benchmark_Table!$G$2:$G$136,0),MATCH('Rev. Build'!$B$7,Benchmark_Table!$H$1:$BL$1,0)),AZ$7) -> 0.15 | BJ7: =_xlfn.IFNA(INDEX(Benchmark_Table!$H$2:$BL$136,MATCH('Rev. Build'!$B$4&'Rev. Build'!BJ$5&BJ$6,Benchmark_Table!$G$2:$G$136,0),MATCH('Rev. Build'!$B$7,Benchmark_Table!$H$1:$BL$1,0)),BE$7) -> 0.15
A8: Revenue Benchmark | B8: =IF(OR('Customer''s Questionnaire'!J10="Too Low",'Customer''s Questionnaire'!J10="Low"),Benchmark_Table!AI1,IF(OR('Customer''s Questionnaire'!J10="Too High",'Customer''s Questionnaire'!J10="High"),Benchmark_Table!AK1,Benchmark_Table!AJ1)) -> Revenue_High_$ | G8: =_xlfn.IFNA(INDEX(Benchmark_Table!$H$2:$BL$136,MATCH('Rev. Build'!$B$4&'Rev. Build'!G$5&G$6,Benchmark_Table!$G$2:$G$136,0),MATCH($B$8,Benchmark_Table!$H$1:$BL$1,0)),0) -> 0 | L8: =_xlfn.IFNA(INDEX(Benchmark_Table!$H$2:$BL$136,MATCH('Rev. Build'!$B$4&'Rev. Build'!L$5&L$6,Benchmark_Table!$G$2:$G$136,0),MATCH($B$8,Benchmark_Table!$H$1:$BL$1,0)),0) -> 80000000 | Q8: =_xlfn.IFNA(INDEX(Benchmark_Table!$H$2:$BL$136,MATCH('Rev. Build'!$B$4&'Rev. Build'!Q$5&Q$6,Benchmark_Table!$G$2:$G$136,0),MATCH($B$8,Benchmark_Table!$H$1:$BL$1,0)),0) -> 0 | V8: =_xlfn.IFNA(INDEX(Benchmark_Table!$H$2:$BL$136,MATCH('Rev. Build'!$B$4&'Rev. Build'!V$5&V$6,Benchmark_Table!$G$2:$G$136,0),MATCH($B$8,Benchmark_Table!$H$1:$BL$1,0)),0) -> 240000000 | AA8: =_xlfn.IFNA(INDEX(Benchmark_Table!$H$2:$BL$136,MATCH('Rev. Build'!$B$4&'Rev. Build'!AA$5&AA$6,Benchmark_Table!$G$2:$G$136,0),MATCH($B$8,Benchmark_Table!$H$1:$BL$1,0)),0) -> 640000000 | AF8: =_xlfn.IFNA(INDEX(Benchmark_Table!$H$2:$BL$136,MATCH('Rev. Build'!$B$4&'Rev. Build'!AF$5&AF$6,Benchmark_Table!$G$2:$G$136,0),MATCH($B$8,Benchmark_Table!$H$1:$BL$1,0)),0) -> 0 | AK8: =_xlfn.IFNA(INDEX(Benchmark_Table!$H$2:$BL$136,MATCH('Rev. Build'!$B$4&'Rev. Build'!AK$5&AK$6,Benchmark_Table!$G$2:$G$136,0),MATCH($B$8,Benchmark_Table!$H$1:$BL$1,0)),0) -> 0 | AP8: =_xlfn.IFNA(INDEX(Benchmark_Table!$H$2:$BL$136,MATCH('Rev. Build'!$B$4&'Rev. Build'!AP$5&AP$6,Benchmark_Table!$G$2:$G$136,0),MATCH($B$8,Benchmark_Table!$H$1:$BL$1,0)),0) -> 0 | AU8: =_xlfn.IFNA(INDEX(Benchmark_Table!$H$2:$BL$136,MATCH('Rev. Build'!$B$4&'Rev. Build'!AU$5&AU$6,Benchmark_Table!$G$2:$G$136,0),MATCH($B$8,Benchmark_Table!$H$1:$BL$1,0)),0) -> 0 | AZ8: =_xlfn.IFNA(INDEX(Benchmark_Table!$H$2:$BL$136,MATCH('Rev. Build'!$B$4&'Rev. Build'!AZ$5&AZ$6,Benchmark_Table!$G$2:$G$136,0),MATCH($B$8,Benchmark_Table!$H$1:$BL$1,0)),0) -> 0 | BE8: =_xlfn.IFNA(INDEX(Benchmark_Table!$H$2:$BL$136,MATCH('Rev. Build'!$B$4&'Rev. Build'!BE$5&BE$6,Benchmark_Table!$G$2:$G$136,0),MATCH($B$8,Benchmark_Table!$H$1:$BL$1,0)),0) -> 0 | BJ8: =_xlfn.IFNA(INDEX(Benchmark_Table!$H$2:$BL$136,MATCH('Rev. Build'!$B$4&'Rev. Build'!BJ$5&BJ$6,Benchmark_Table!$G$2:$G$136,0),MATCH($B$8,Benchmark_Table!$H$1:$BL$1,0)),0) -> 0
G9: Q. | H9: Q. | I9: Q. | J9: Q. | K9: Q. | L9: Q. | M9: Q. | N9: Q. | O9: Q. | P9: Q. | Q9: Q. | R9: Q. | S9: Q. | T9: Q. | U9: Q. | V9: Q. | W9: Q. | X9: Q. | Y9: Q. | Z9: Q. | AA9: Q. | AB9: Q. | AC9: Q. | AD9: Q. | AE9: Q. | AF9: Q. | AG9: Q. | AH9: Q. | AI9: Q. | AJ9: Q. | AK9: Q. | AL9: Q. | AM9: Q. | AN9: Q. | AO9: Q. | AP9: Q. | AQ9: Q. | AR9: Q. | AS9: Q. | AT9: Q. | AU9: Q. | AV9: Q. | AW9: Q. | AX9: Q. | AY9: Q. | AZ9: Q. | BA9: Q. | BB9: Q. | BC9: Q. | BD9: Q. | BE9: Q. | BF9: Q. | BG9: Q. | BH9: Q. | BI9: Q. | BJ9: Q. | BK9: Q. | BL9: Q. | BM9: Q. | BN9: Q.
A10: Revenue Type | B10: Customer Name | C10: Type | D10: Territory | E10: Product Name | F10: Notes | G10: ="Q1-"&'Customer''s Questionnaire'!$I$12 -> Q1-2026 | H10: ="Q2-"&'Customer''s Questionnaire'!$I$12 -> Q2-2026 | I10: ="Q3-"&'Customer''s Questionnaire'!$I$12 -> Q3-2026 | J10: ="Q4-"&'Customer''s Questionnaire'!$I$12 -> Q4-2026 | K10: ='Customer''s Questionnaire'!$I$12 -> 2026 | L10: ="Q1-"&K$10+1 -> Q1-2027 | M10: ="Q2-"&K$10+1 -> Q2-2027 | N10: ="Q3-"&K$10+1 -> Q3-2027 | O10: ="Q4-"&K$10+1 -> Q4-2027 | P10: =K10+1 -> 2027 | Q10: ="Q1-"&P$10+1 -> Q1-2028 | R10: ="Q2-"&P$10+1 -> Q2-2028 | S10: ="Q3-"&P$10+1 -> Q3-2028 | T10: ="Q4-"&P$10+1 -> Q4-2028 | U10: =P10+1 -> 2028 | V10: ="Q1-"&U$10+1 -> Q1-2029 | W10: ="Q2-"&U$10+1 -> Q2-2029 | X10: ="Q3-"&U$10+1 -> Q3-2029 | Y10: ="Q4-"&U$10+1 -> Q4-2029 | Z10: =U10+1 -> 2029 | AA10: ="Q1-"&Z$10+1 -> Q1-2030 | AB10: ="Q2-"&Z$10+1 -> Q2-2030 | AC10: ="Q3-"&Z$10+1 -> Q3-2030 | AD10: ="Q4-"&Z$10+1 -> Q4-2030 | AE10: =Z10+1 -> 2030 | AF10: ="Q1-"&AE$10+1 -> Q1-2031 | AG10: ="Q2-"&AE$10+1 -> Q2-2031 | AH10: ="Q3-"&AE$10+1 -> Q3-2031 | AI10: ="Q4-"&AE$10+1 -> Q4-2031 | AJ10: =AE10+1 -> 2031 | AK10: ="Q1-"&AJ$10+1 -> Q1-2032 | AL10: ="Q2-"&AJ$10+1 -> Q2-2032 | AM10: ="Q3-"&AJ$10+1 -> Q3-2032 | AN10: ="Q4-"&AJ$10+1 -> Q4-2032 | AO10: =AJ10+1 -> 2032 | AP10: ="Q1-"&AO$10+1 -> Q1-2033 | AQ10: ="Q2-"&AO$10+1 -> Q2-2033 | AR10: ="Q3-"&AO$10+1 -> Q3-2033 | AS10: ="Q4-"&AO$10+1 -> Q4-2033 | AT10: =AO10+1 -> 2033 | AU10: ="Q1-"&AT$10+1 -> Q1-2034 | AV10: ="Q2-"&AT$10+1 -> Q2-2034 | AW10: ="Q3-"&AT$10+1 -> Q3-2034 | AX10: ="Q4-"&AT$10+1 -> Q4-2034 | AY10: =AT10+1 -> 2034 | AZ10: ="Q1-"&AY$10+1 -> Q1-2035 | BA10: ="Q2-"&AY$10+1 -> Q2-2035 | BB10: ="Q3-"&AY$10+1 -> Q3-2035 | BC10: ="Q4-"&AY$10+1 -> Q4-2035 | BD10: =AY10+1 -> 2035 | BE10: ="Q1-"&BD$10+1 -> Q1-2036 | BF10: ="Q2-"&BD$10+1 -> Q2-2036 | BG10: ="Q3-"&BD$10+1 -> Q3-2036 | BH10: ="Q4-"&BD$10+1 -> Q4-2036 | BI10: =BD10+1 -> 2036 | BJ10: ="Q1-"&BI$10+1 -> Q1-2037 | BK10: ="Q2-"&BI$10+1 -> Q2-2037 | BL10: ="Q3-"&BI$10+1 -> Q3-2037 | BM10: ="Q4-"&BI$10+1 -> Q4-2037 | BN10: =BI10+1 -> 2037
A11: ='Customer''s Questionnaire'!H44 -> Hardware | B11: ='Customer''s Questionnaire'!I44 -> Hungry AF | C11: ='Customer''s Questionnaire'!J44 -> B2C | D11: ='Customer''s Questionnaire'!K44 -> US | E11: ='Customer''s Questionnaire'!L44 -> Big MAC | G11: ='Customer''s Questionnaire'!O44 -> 10 | H11: ='Customer''s Questionnaire'!P44 -> 10 | I11: ='Customer''s Questionnaire'!Q44 -> 10 | J11: ='Customer''s Questionnaire'!R44 -> 10 | K11: =SUM(G11:J11) -> 40 | L11: =IFERROR('Customer''s Questionnaire'!$S44/4,"Add if needed") -> 12.5 | M11: =IFERROR('Customer''s Questionnaire'!$S44/4,"Add if needed") -> 12.5 | N11: =IFERROR('Customer''s Questionnaire'!$S44/4,"Add if needed") -> 12.5 | O11: =IFERROR('Customer''s Questionnaire'!$S44/4,"Add if needed") -> 12.5 | P11: =SUM(L11:O11) -> 50 | Q11: =IFERROR($P11/4*(1+$Q$7),0) -> 16.875 | R11: =IFERROR($P11/4*(1+$Q$7),0) -> 16.875 | S11: =IFERROR($P11/4*(1+$Q$7),0) -> 16.875 | T11: =IFERROR($P11/4*(1+$Q$7),0) -> 16.875 | U11: =SUM(Q11:T11) -> 67.5 | V11: =IFERROR($U11/4*(1+$V$7),0) -> 21.09375 | W11: =IFERROR($U11/4*(1+$V$7),0) -> 21.09375 | X11: =IFERROR($U11/4*(1+$V$7),0) -> 21.09375 | Y11: =IFERROR($U11/4*(1+$V$7),0) -> 21.09375 | Z11: =SUM(V11:Y11) -> 84.375 | AA11: =IFERROR($Z11/4*(1+$AA$7),0) -> 24.257812 | AB11: =IFERROR($Z11/4*(1+$AA$7),0) -> 24.257812 | AC11: =IFERROR($Z11/4*(1+$AA$7),0) -> 24.257812 | AD11: =IFERROR($Z11/4*(1+$AA$7),0) -> 24.257812 | AE11: =SUM(AA11:AD11) -> 97.03125 | AF11: =IFERROR($AE11/4*(1+$AF$7),0) -> 27.896484 | AG11: =IFERROR($AE11/4*(1+$AF$7),0) -> 27.896484 | AH11: =IFERROR($AE11/4*(1+$AF$7),0) -> 27.896484 | AI11: =IFERROR($AE11/4*(1+$AF$7),0) -> 27.896484 | AJ11: =SUM(AF11:AI11) -> 111.58594 | AK11: =IFERROR($AJ11/4*(1+$AK$7),0) -> 32.080957 | AL11: =IFERROR($AJ11/4*(1+$AK$7),0) -> 32.080957 | AM11: =IFERROR($AJ11/4*(1+$AK$7),0) -> 32.080957 | AN11: =IFERROR($AJ11/4*(1+$AK$7),0) -> 32.080957 | AO11: =SUM(AK11:AN11) -> 128.32383 | AP11: =IFERROR($AO11/4*(1+$AP$7),0) -> 36.893101 | AQ11: =IFERROR($AO11/4*(1+$AP$7),0) -> 36.893101 | AR11: =IFERROR($AO11/4*(1+$AP$7),0) -> 36.893101 | AS11: =IFERROR($AO11/4*(1+$AP$7),0) -> 36.893101 | AT11: =SUM(AP11:AS11) -> 147.5724 | AU11: =IFERROR($AT11/4*(1+$AU$7),0) -> 42.427066 | AV11: =IFERROR($AT11/4*(1+$AU$7),0) -> 42.427066 | AW11: =IFERROR($AT11/4*(1+$AU$7),0) -> 42.427066 | AX11: =IFERROR($AT11/4*(1+$AU$7),0) -> 42.427066 | AY11: =SUM(AU11:AX11) -> 169.70826 | AZ11: =IFERROR($AY11/4*(1+$AZ$7),0) -> 48.791126 | BA11: =IFERROR($AY11/4*(1+$AZ$7),0) -> 48.791126 | BB11: =IFERROR($AY11/4*(1+$AZ$7),0) -> 48.791126 | BC11: =IFERROR($AY11/4*(1+$AZ$7),0) -> 48.791126 | BD11: =SUM(AZ11:BC11) -> 195.1645 | BE11: =IFERROR($BD11/4*(1+$BE$7),0) -> 56.109794 | BF11: =IFERROR($BD11/4*(1+$BE$7),0) -> 56.109794 | BG11: =IFERROR($BD11/4*(1+$BE$7),0) -> 56.109794 | BH11: =IFERROR($BD11/4*(1+$BE$7),0) -> 56.109794 | BI11: =SUM(BE11:BH11) -> 224.43918 | BJ11: =IFERROR($BI11/4*(1+$BJ$7),0) -> 64.526264 | BK11: =IFERROR($BI11/4*(1+$BJ$7),0) -> 64.526264 | BL11: =IFERROR($BI11/4*(1+$BJ$7),0) -> 64.526264 | BM11: =IFERROR($BI11/4*(1+$BJ$7),0) -> 64.526264 | BN11: =SUM(BJ11:BM11) -> 258.10505
A12: ='Customer''s Questionnaire'!H45 -> Software / SaaS | B12: ='Customer''s Questionnaire'!I45 -> BULO | C12: ='Customer''s Questionnaire'!J45 -> Direct | D12: ='Customer''s Questionnaire'!K45 -> EU | E12: ='Customer''s Questionnaire'!L45 -> MCMC | G12: ='Customer''s Questionnaire'!O45 -> 1000 | H12: ='Customer''s Questionnaire'!P45 -> 1000 | I12: ='Customer''s Questionnaire'!Q45 -> 1000 | J12: ='Customer''s Questionnaire'!R45 -> 1000 | K12: =SUM(G12:J12) -> 4000 | L12: =IFERROR('Customer''s Questionnaire'!$S45/4,"Add if needed") -> 1250 | M12: =IFERROR('Customer''s Questionnaire'!$S45/4,"Add if needed") -> 1250 | N12: =IFERROR('Customer''s Questionnaire'!$S45/4,"Add if needed") -> 1250 | O12: =IFERROR('Customer''s Questionnaire'!$S45/4,"Add if needed") -> 1250 | P12: =SUM(L12:O12) -> 5000 | Q12: =IFERROR($P12/4*(1+$Q$7),0) -> 1687.5 | R12: =IFERROR($P12/4*(1+$Q$7),0) -> 1687.5 | S12: =IFERROR($P12/4*(1+$Q$7),0) -> 1687.5 | T12: =IFERROR($P12/4*(1+$Q$7),0) -> 1687.5 | U12: =SUM(Q12:T12) -> 6750 | V12: =IFERROR($U12/4*(1+$V$7),0) -> 2109.375 | W12: =IFERROR($U12/4*(1+$V$7),0) -> 2109.375 | X12: =IFERROR($U12/4*(1+$V$7),0) -> 2109.375 | Y12: =IFERROR($U12/4*(1+$V$7),0) -> 2109.375 | Z12: =SUM(V12:Y12) -> 8437.5 | AA12: =IFERROR($Z12/4*(1+$AA$7),0) -> 2425.7812 | AB12: =IFERROR($Z12/4*(1+$AA$7),0) -> 2425.7812 | AC12: =IFERROR($Z12/4*(1+$AA$7),0) -> 2425.7812 | AD12: =IFERROR($Z12/4*(1+$AA$7),0) -> 2425.7812 | AE12: =SUM(AA12:AD12) -> 9703.125 | AF12: =IFERROR($AE12/4*(1+$AF$7),0) -> 2789.6484 | AG12: =IFERROR($AE12/4*(1+$AF$7),0) -> 2789.6484 | AH12: =IFERROR($AE12/4*(1+$AF$7),0) -> 2789.6484 | AI12: =IFERROR($AE12/4*(1+$AF$7),0) -> 2789.6484 | AJ12: =SUM(AF12:AI12) -> 11158.594 | AK12: =IFERROR($AJ12/4*(1+$AK$7),0) -> 3208.0957 | AL12: =IFERROR($AJ12/4*(1+$AK$7),0) -> 3208.0957 | AM12: =IFERROR($AJ12/4*(1+$AK$7),0) -> 3208.0957 | AN12: =IFERROR($AJ12/4*(1+$AK$7),0) -> 3208.0957 | AO12: =SUM(AK12:AN12) -> 12832.383 | AP12: =IFERROR($AO12/4*(1+$AP$7),0) -> 3689.3101 | AQ12: =IFERROR($AO12/4*(1+$AP$7),0) -> 3689.3101 | AR12: =IFERROR($AO12/4*(1+$AP$7),0) -> 3689.3101 | AS12: =IFERROR($AO12/4*(1+$AP$7),0) -> 3689.3101 | AT12: =SUM(AP12:AS12) -> 14757.24 | AU12: =IFERROR($AT12/4*(1+$AU$7),0) -> 4242.7066 | AV12: =IFERROR($AT12/4*(1+$AU$7),0) -> 4242.7066 | AW12: =IFERROR($AT12/4*(1+$AU$7),0) -> 4242.7066 | AX12: =IFERROR($AT12/4*(1+$AU$7),0) -> 4242.7066 | AY12: =SUM(AU12:AX12) -> 16970.826 | AZ12: =IFERROR($AY12/4*(1+$AZ$7),0) -> 4879.1126 | BA12: =IFERROR($AY12/4*(1+$AZ$7),0) -> 4879.1126 | BB12: =IFERROR($AY12/4*(1+$AZ$7),0) -> 4879.1126 | BC12: =IFERROR($AY12/4*(1+$AZ$7),0) -> 4879.1126 | BD12: =SUM(AZ12:BC12) -> 19516.45 | BE12: =IFERROR($BD12/4*(1+$BE$7),0) -> 5610.9794 | BF12: =IFERROR($BD12/4*(1+$BE$7),0) -> 5610.9794 | BG12: =IFERROR($BD12/4*(1+$BE$7),0) -> 5610.9794 | BH12: =IFERROR($BD12/4*(1+$BE$7),0) -> 5610.9794 | BI12: =SUM(BE12:BH12) -> 22443.918 | BJ12: =IFERROR($BI12/4*(1+$BJ$7),0) -> 6452.6264 | BK12: =IFERROR($BI12/4*(1+$BJ$7),0) -> 6452.6264 | BL12: =IFERROR($BI12/4*(1+$BJ$7),0) -> 6452.6264 | BM12: =IFERROR($BI12/4*(1+$BJ$7),0) -> 6452.6264 | BN12: =SUM(BJ12:BM12) -> 25810.505
A13: ='Customer''s Questionnaire'!H46 -> 0 | B13: ='Customer''s Questionnaire'!I46 -> 0 | C13: ='Customer''s Questionnaire'!J46 -> 0 | D13: ='Customer''s Questionnaire'!K46 -> 0 | E13: ='Customer''s Questionnaire'!L46 -> 0 | G13: ='Customer''s Questionnaire'!O46 -> 0 | H13: ='Customer''s Questionnaire'!P46 -> 0 | I13: ='Customer''s Questionnaire'!Q46 -> 0 | J13: ='Customer''s Questionnaire'!R46 -> 0 | K13: =SUM(G13:J13) -> 0 | L13: =IFERROR('Customer''s Questionnaire'!$S46/4,"Add if needed") -> 0 | M13: =IFERROR('Customer''s Questionnaire'!$S46/4,"Add if needed") -> 0 | N13: =IFERROR('Customer''s Questionnaire'!$S46/4,"Add if needed") -> 0 | O13: =IFERROR('Customer''s Questionnaire'!$S46/4,"Add if needed") -> 0 | P13: =SUM(L13:O13) -> 0 | Q13: =IFERROR($P13/4*(1+$Q$7),0) -> 0 | R13: =IFERROR($P13/4*(1+$Q$7),0) -> 0 | S13: =IFERROR($P13/4*(1+$Q$7),0) -> 0 | T13: =IFERROR($P13/4*(1+$Q$7),0) -> 0 | U13: =SUM(Q13:T13) -> 0 | V13: =IFERROR($U13/4*(1+$V$7),0) -> 0 | W13: =IFERROR($U13/4*(1+$V$7),0) -> 0 | X13: =IFERROR($U13/4*(1+$V$7),0) -> 0 | Y13: =IFERROR($U13/4*(1+$V$7),0) -> 0 | Z13: =SUM(V13:Y13) -> 0 | AA13: =IFERROR($Z13/4*(1+$AA$7),0) -> 0 | AB13: =IFERROR($Z13/4*(1+$AA$7),0) -> 0 | AC13: =IFERROR($Z13/4*(1+$AA$7),0) -> 0 | AD13: =IFERROR($Z13/4*(1+$AA$7),0) -> 0 | AE13: =SUM(AA13:AD13) -> 0 | AF13: =IFERROR($AE13/4*(1+$AF$7),0) -> 0 | AG13: =IFERROR($AE13/4*(1+$AF$7),0) -> 0 | AH13: =IFERROR($AE13/4*(1+$AF$7),0) -> 0 | AI13: =IFERROR($AE13/4*(1+$AF$7),0) -> 0 | AJ13: =SUM(AF13:AI13) -> 0 | AK13: =IFERROR($AJ13/4*(1+$AK$7),0) -> 0 | AL13: =IFERROR($AJ13/4*(1+$AK$7),0) -> 0 | AM13: =IFERROR($AJ13/4*(1+$AK$7),0) -> 0 | AN13: =IFERROR($AJ13/4*(1+$AK$7),0) -> 0 | AO13: =SUM(AK13:AN13) -> 0 | AP13: =IFERROR($AO13/4*(1+$AP$7),0) -> 0 | AQ13: =IFERROR($AO13/4*(1+$AP$7),0) -> 0 | AR13: =IFERROR($AO13/4*(1+$AP$7),0) -> 0 | AS13: =IFERROR($AO13/4*(1+$AP$7),0) -> 0 | AT13: =SUM(AP13:AS13) -> 0 | AU13: =IFERROR($AT13/4*(1+$AU$7),0) -> 0 | AV13: =IFERROR($AT13/4*(1+$AU$7),0) -> 0 | AW13: =IFERROR($AT13/4*(1+$AU$7),0) -> 0 | AX13: =IFERROR($AT13/4*(1+$AU$7),0) -> 0 | AY13: =SUM(AU13:AX13) -> 0 | AZ13: =IFERROR($AY13/4*(1+$AZ$7),0) -> 0 | BA13: =IFERROR($AY13/4*(1+$AZ$7),0) -> 0 | BB13: =IFERROR($AY13/4*(1+$AZ$7),0) -> 0 | BC13: =IFERROR($AY13/4*(1+$AZ$7),0) -> 0 | BD13: =SUM(AZ13:BC13) -> 0 | BE13: =IFERROR($BD13/4*(1+$BE$7),0) -> 0 | BF13: =IFERROR($BD13/4*(1+$BE$7),0) -> 0 | BG13: =IFERROR($BD13/4*(1+$BE$7),0) -> 0 | BH13: =IFERROR($BD13/4*(1+$BE$7),0) -> 0 | BI13: =SUM(BE13:BH13) -> 0 | BJ13: =IFERROR($BI13/4*(1+$BJ$7),0) -> 0 | BK13: =IFERROR($BI13/4*(1+$BJ$7),0) -> 0 | BL13: =IFERROR($BI13/4*(1+$BJ$7),0) -> 0 | BM13: =IFERROR($BI13/4*(1+$BJ$7),0) -> 0 | BN13: =SUM(BJ13:BM13) -> 0
A14: ='Customer''s Questionnaire'!H47 -> 0 | B14: ='Customer''s Questionnaire'!I47 -> 0 | C14: ='Customer''s Questionnaire'!J47 -> 0 | D14: ='Customer''s Questionnaire'!K47 -> 0 | E14: ='Customer''s Questionnaire'!L47 -> 0 | G14: ='Customer''s Questionnaire'!O47 -> 0 | H14: ='Customer''s Questionnaire'!P47 -> 0 | I14: ='Customer''s Questionnaire'!Q47 -> 0 | J14: ='Customer''s Questionnaire'!R47 -> 0 | K14: =SUM(G14:J14) -> 0 | L14: =IFERROR('Customer''s Questionnaire'!$S47/4,"Add if needed") -> 0 | M14: =IFERROR('Customer''s Questionnaire'!$S47/4,"Add if needed") -> 0 | N14: =IFERROR('Customer''s Questionnaire'!$S47/4,"Add if needed") -> 0 | O14: =IFERROR('Customer''s Questionnaire'!$S47/4,"Add if needed") -> 0 | P14: =SUM(L14:O14) -> 0 | Q14: =IFERROR($P14/4*(1+$Q$7),0) -> 0 | R14: =IFERROR($P14/4*(1+$Q$7),0) -> 0 | S14: =IFERROR($P14/4*(1+$Q$7),0) -> 0 | T14: =IFERROR($P14/4*(1+$Q$7),0) -> 0 | U14: =SUM(Q14:T14) -> 0 | V14: =IFERROR($U14/4*(1+$V$7),0) -> 0 | W14: =IFERROR($U14/4*(1+$V$7),0) -> 0 | X14: =IFERROR($U14/4*(1+$V$7),0) -> 0 | Y14: =IFERROR($U14/4*(1+$V$7),0) -> 0 | Z14: =SUM(V14:Y14) -> 0 | AA14: =IFERROR($Z14/4*(1+$AA$7),0) -> 0 | AB14: =IFERROR($Z14/4*(1+$AA$7),0) -> 0 | AC14: =IFERROR($Z14/4*(1+$AA$7),0) -> 0 | AD14: =IFERROR($Z14/4*(1+$AA$7),0) -> 0 | AE14: =SUM(AA14:AD14) -> 0 | AF14: =IFERROR($AE14/4*(1+$AF$7),0) -> 0 | AG14: =IFERROR($AE14/4*(1+$AF$7),0) -> 0 | AH14: =IFERROR($AE14/4*(1+$AF$7),0) -> 0 | AI14: =IFERROR($AE14/4*(1+$AF$7),0) -> 0 | AJ14: =SUM(AF14:AI14) -> 0 | AK14: =IFERROR($AJ14/4*(1+$AK$7),0) -> 0 | AL14: =IFERROR($AJ14/4*(1+$AK$7),0) -> 0 | AM14: =IFERROR($AJ14/4*(1+$AK$7),0) -> 0 | AN14: =IFERROR($AJ14/4*(1+$AK$7),0) -> 0 | AO14: =SUM(AK14:AN14) -> 0 | AP14: =IFERROR($AO14/4*(1+$AP$7),0) -> 0 | AQ14: =IFERROR($AO14/4*(1+$AP$7),0) -> 0 | AR14: =IFERROR($AO14/4*(1+$AP$7),0) -> 0 | AS14: =IFERROR($AO14/4*(1+$AP$7),0) -> 0 | AT14: =SUM(AP14:AS14) -> 0 | AU14: =IFERROR($AT14/4*(1+$AU$7),0) -> 0 | AV14: =IFERROR($AT14/4*(1+$AU$7),0) -> 0 | AW14: =IFERROR($AT14/4*(1+$AU$7),0) -> 0 | AX14: =IFERROR($AT14/4*(1+$AU$7),0) -> 0 | AY14: =SUM(AU14:AX14) -> 0 | AZ14: =IFERROR($AY14/4*(1+$AZ$7),0) -> 0 | BA14: =IFERROR($AY14/4*(1+$AZ$7),0) -> 0 | BB14: =IFERROR($AY14/4*(1+$AZ$7),0) -> 0 | BC14: =IFERROR($AY14/4*(1+$AZ$7),0) -> 0 | BD14: =SUM(AZ14:BC14) -> 0 | BE14: =IFERROR($BD14/4*(1+$BE$7),0) -> 0 | BF14: =IFERROR($BD14/4*(1+$BE$7),0) -> 0 | BG14: =IFERROR($BD14/4*(1+$BE$7),0) -> 0 | BH14: =IFERROR($BD14/4*(1+$BE$7),0) -> 0 | BI14: =SUM(BE14:BH14) -> 0 | BJ14: =IFERROR($BI14/4*(1+$BJ$7),0) -> 0 | BK14: =IFERROR($BI14/4*(1+$BJ$7),0) -> 0 | BL14: =IFERROR($BI14/4*(1+$BJ$7),0) -> 0 | BM14: =IFERROR($BI14/4*(1+$BJ$7),0) -> 0 | BN14: =SUM(BJ14:BM14) -> 0
A15: ='Customer''s Questionnaire'!H48 -> 0 | B15: ='Customer''s Questionnaire'!I48 -> 0 | C15: ='Customer''s Questionnaire'!J48 -> 0 | D15: ='Customer''s Questionnaire'!K48 -> 0 | E15: ='Customer''s Questionnaire'!L48 -> 0 | G15: ='Customer''s Questionnaire'!O48 -> 0 | H15: ='Customer''s Questionnaire'!P48 -> 0 | I15: ='Customer''s Questionnaire'!Q48 -> 0 | J15: ='Customer''s Questionnaire'!R48 -> 0 | K15: =SUM(G15:J15) -> 0 | L15: =IFERROR('Customer''s Questionnaire'!$S48/4,"Add if needed") -> 0 | M15: =IFERROR('Customer''s Questionnaire'!$S48/4,"Add if needed") -> 0 | N15: =IFERROR('Customer''s Questionnaire'!$S48/4,"Add if needed") -> 0 | O15: =IFERROR('Customer''s Questionnaire'!$S48/4,"Add if needed") -> 0 | P15: =SUM(L15:O15) -> 0 | Q15: =IFERROR($P15/4*(1+$Q$7),0) -> 0 | R15: =IFERROR($P15/4*(1+$Q$7),0) -> 0 | S15: =IFERROR($P15/4*(1+$Q$7),0) -> 0 | T15: =IFERROR($P15/4*(1+$Q$7),0) -> 0 | U15: =SUM(Q15:T15) -> 0 | V15: =IFERROR($U15/4*(1+$V$7),0) -> 0 | W15: =IFERROR($U15/4*(1+$V$7),0) -> 0 | X15: =IFERROR($U15/4*(1+$V$7),0) -> 0 | Y15: =IFERROR($U15/4*(1+$V$7),0) -> 0 | Z15: =SUM(V15:Y15) -> 0 | AA15: =IFERROR($Z15/4*(1+$AA$7),0) -> 0 | AB15: =IFERROR($Z15/4*(1+$AA$7),0) -> 0 | AC15: =IFERROR($Z15/4*(1+$AA$7),0) -> 0 | AD15: =IFERROR($Z15/4*(1+$AA$7),0) -> 0 | AE15: =SUM(AA15:AD15) -> 0 | AF15: =IFERROR($AE15/4*(1+$AF$7),0) -> 0 | AG15: =IFERROR($AE15/4*(1+$AF$7),0) -> 0 | AH15: =IFERROR($AE15/4*(1+$AF$7),0) -> 0 | AI15: =IFERROR($AE15/4*(1+$AF$7),0) -> 0 | AJ15: =SUM(AF15:AI15) -> 0 | AK15: =IFERROR($AJ15/4*(1+$AK$7),0) -> 0 | AL15: =IFERROR($AJ15/4*(1+$AK$7),0) -> 0 | AM15: =IFERROR($AJ15/4*(1+$AK$7),0) -> 0 | AN15: =IFERROR($AJ15/4*(1+$AK$7),0) -> 0 | AO15: =SUM(AK15:AN15) -> 0 | AP15: =IFERROR($AO15/4*(1+$AP$7),0) -> 0 | AQ15: =IFERROR($AO15/4*(1+$AP$7),0) -> 0 | AR15: =IFERROR($AO15/4*(1+$AP$7),0) -> 0 | AS15: =IFERROR($AO15/4*(1+$AP$7),0) -> 0 | AT15: =SUM(AP15:AS15) -> 0 | AU15: =IFERROR($AT15/4*(1+$AU$7),0) -> 0 | AV15: =IFERROR($AT15/4*(1+$AU$7),0) -> 0 | AW15: =IFERROR($AT15/4*(1+$AU$7),0) -> 0 | AX15: =IFERROR($AT15/4*(1+$AU$7),0) -> 0 | AY15: =SUM(AU15:AX15) -> 0 | AZ15: =IFERROR($AY15/4*(1+$AZ$7),0) -> 0 | BA15: =IFERROR($AY15/4*(1+$AZ$7),0) -> 0 | BB15: =IFERROR($AY15/4*(1+$AZ$7),0) -> 0 | BC15: =IFERROR($AY15/4*(1+$AZ$7),0) -> 0 | BD15: =SUM(AZ15:BC15) -> 0 | BE15: =IFERROR($BD15/4*(1+$BE$7),0) -> 0 | BF15: =IFERROR($BD15/4*(1+$BE$7),0) -> 0 | BG15: =IFERROR($BD15/4*(1+$BE$7),0) -> 0 | BH15: =IFERROR($BD15/4*(1+$BE$7),0) -> 0 | BI15: =SUM(BE15:BH15) -> 0 | BJ15: =IFERROR($BI15/4*(1+$BJ$7),0) -> 0 | BK15: =IFERROR($BI15/4*(1+$BJ$7),0) -> 0 | BL15: =IFERROR($BI15/4*(1+$BJ$7),0) -> 0 | BM15: =IFERROR($BI15/4*(1+$BJ$7),0) -> 0 | BN15: =SUM(BJ15:BM15) -> 0
A16: ='Customer''s Questionnaire'!H49 -> 0 | B16: ='Customer''s Questionnaire'!I49 -> 0 | C16: ='Customer''s Questionnaire'!J49 -> 0 | D16: ='Customer''s Questionnaire'!K49 -> 0 | E16: ='Customer''s Questionnaire'!L49 -> 0 | G16: ='Customer''s Questionnaire'!O49 -> 0 | H16: ='Customer''s Questionnaire'!P49 -> 0 | I16: ='Customer''s Questionnaire'!Q49 -> 0 | J16: ='Customer''s Questionnaire'!R49 -> 0 | K16: =SUM(G16:J16) -> 0 | L16: =IFERROR('Customer''s Questionnaire'!$S49/4,"Add if needed") -> 0 | M16: =IFERROR('Customer''s Questionnaire'!$S49/4,"Add if needed") -> 0 | N16: =IFERROR('Customer''s Questionnaire'!$S49/4,"Add if needed") -> 0 | O16: =IFERROR('Customer''s Questionnaire'!$S49/4,"Add if needed") -> 0 | P16: =SUM(L16:O16) -> 0 | Q16: =IFERROR($P16/4*(1+$Q$7),0) -> 0 | R16: =IFERROR($P16/4*(1+$Q$7),0) -> 0 | S16: =IFERROR($P16/4*(1+$Q$7),0) -> 0 | T16: =IFERROR($P16/4*(1+$Q$7),0) -> 0 | U16: =SUM(Q16:T16) -> 0 | V16: =IFERROR($U16/4*(1+$V$7),0) -> 0 | W16: =IFERROR($U16/4*(1+$V$7),0) -> 0 | X16: =IFERROR($U16/4*(1+$V$7),0) -> 0 | Y16: =IFERROR($U16/4*(1+$V$7),0) -> 0 | Z16: =SUM(V16:Y16) -> 0 | AA16: =IFERROR($Z16/4*(1+$AA$7),0) -> 0 | AB16: =IFERROR($Z16/4*(1+$AA$7),0) -> 0 | AC16: =IFERROR($Z16/4*(1+$AA$7),0) -> 0 | AD16: =IFERROR($Z16/4*(1+$AA$7),0) -> 0 | AE16: =SUM(AA16:AD16) -> 0 | AF16: =IFERROR($AE16/4*(1+$AF$7),0) -> 0 | AG16: =IFERROR($AE16/4*(1+$AF$7),0) -> 0 | AH16: =IFERROR($AE16/4*(1+$AF$7),0) -> 0 | AI16: =IFERROR($AE16/4*(1+$AF$7),0) -> 0 | AJ16: =SUM(AF16:AI16) -> 0 | AK16: =IFERROR($AJ16/4*(1+$AK$7),0) -> 0 | AL16: =IFERROR($AJ16/4*(1+$AK$7),0) -> 0 | AM16: =IFERROR($AJ16/4*(1+$AK$7),0) -> 0 | AN16: =IFERROR($AJ16/4*(1+$AK$7),0) -> 0 | AO16: =SUM(AK16:AN16) -> 0 | AP16: =IFERROR($AO16/4*(1+$AP$7),0) -> 0 | AQ16: =IFERROR($AO16/4*(1+$AP$7),0) -> 0 | AR16: =IFERROR($AO16/4*(1+$AP$7),0) -> 0 | AS16: =IFERROR($AO16/4*(1+$AP$7),0) -> 0 | AT16: =SUM(AP16:AS16) -> 0 | AU16: =IFERROR($AT16/4*(1+$AU$7),0) -> 0 | AV16: =IFERROR($AT16/4*(1+$AU$7),0) -> 0 | AW16: =IFERROR($AT16/4*(1+$AU$7),0) -> 0 | AX16: =IFERROR($AT16/4*(1+$AU$7),0) -> 0 | AY16: =SUM(AU16:AX16) -> 0 | AZ16: =IFERROR($AY16/4*(1+$AZ$7),0) -> 0 | BA16: =IFERROR($AY16/4*(1+$AZ$7),0) -> 0 | BB16: =IFERROR($AY16/4*(1+$AZ$7),0) -> 0 | BC16: =IFERROR($AY16/4*(1+$AZ$7),0) -> 0 | BD16: =SUM(AZ16:BC16) -> 0 | BE16: =IFERROR($BD16/4*(1+$BE$7),0) -> 0 | BF16: =IFERROR($BD16/4*(1+$BE$7),0) -> 0 | BG16: =IFERROR($BD16/4*(1+$BE$7),0) -> 0 | BH16: =IFERROR($BD16/4*(1+$BE$7),0) -> 0 | BI16: =SUM(BE16:BH16) -> 0 | BJ16: =IFERROR($BI16/4*(1+$BJ$7),0) -> 0 | BK16: =IFERROR($BI16/4*(1+$BJ$7),0) -> 0 | BL16: =IFERROR($BI16/4*(1+$BJ$7),0) -> 0 | BM16: =IFERROR($BI16/4*(1+$BJ$7),0) -> 0 | BN16: =SUM(BJ16:BM16) -> 0
A17: ='Customer''s Questionnaire'!H50 -> 0 | B17: ='Customer''s Questionnaire'!I50 -> 0 | C17: ='Customer''s Questionnaire'!J50 -> 0 | D17: ='Customer''s Questionnaire'!K50 -> 0 | E17: ='Customer''s Questionnaire'!L50 -> 0 | G17: ='Customer''s Questionnaire'!O50 -> 0 | H17: ='Customer''s Questionnaire'!P50 -> 0 | I17: ='Customer''s Questionnaire'!Q50 -> 0 | J17: ='Customer''s Questionnaire'!R50 -> 0 | K17: =SUM(G17:J17) -> 0 | L17: =IFERROR('Customer''s Questionnaire'!$S50/4,"Add if needed") -> 0 | M17: =IFERROR('Customer''s Questionnaire'!$S50/4,"Add if needed") -> 0 | N17: =IFERROR('Customer''s Questionnaire'!$S50/4,"Add if needed") -> 0 | O17: =IFERROR('Customer''s Questionnaire'!$S50/4,"Add if needed") -> 0 | P17: =SUM(L17:O17) -> 0 | Q17: =IFERROR($P17/4*(1+$Q$7),0) -> 0 | R17: =IFERROR($P17/4*(1+$Q$7),0) -> 0 | S17: =IFERROR($P17/4*(1+$Q$7),0) -> 0 | T17: =IFERROR($P17/4*(1+$Q$7),0) -> 0 | U17: =SUM(Q17:T17) -> 0 | V17: =IFERROR($U17/4*(1+$V$7),0) -> 0 | W17: =IFERROR($U17/4*(1+$V$7),0) -> 0 | X17: =IFERROR($U17/4*(1+$V$7),0) -> 0 | Y17: =IFERROR($U17/4*(1+$V$7),0) -> 0 | Z17: =SUM(V17:Y17) -> 0 | AA17: =IFERROR($Z17/4*(1+$AA$7),0) -> 0 | AB17: =IFERROR($Z17/4*(1+$AA$7),0) -> 0 | AC17: =IFERROR($Z17/4*(1+$AA$7),0) -> 0 | AD17: =IFERROR($Z17/4*(1+$AA$7),0) -> 0 | AE17: =SUM(AA17:AD17) -> 0 | AF17: =IFERROR($AE17/4*(1+$AF$7),0) -> 0 | AG17: =IFERROR($AE17/4*(1+$AF$7),0) -> 0 | AH17: =IFERROR($AE17/4*(1+$AF$7),0) -> 0 | AI17: =IFERROR($AE17/4*(1+$AF$7),0) -> 0 | AJ17: =SUM(AF17:AI17) -> 0 | AK17: =IFERROR($AJ17/4*(1+$AK$7),0) -> 0 | AL17: =IFERROR($AJ17/4*(1+$AK$7),0) -> 0 | AM17: =IFERROR($AJ17/4*(1+$AK$7),0) -> 0 | AN17: =IFERROR($AJ17/4*(1+$AK$7),0) -> 0 | AO17: =SUM(AK17:AN17) -> 0 | AP17: =IFERROR($AO17/4*(1+$AP$7),0) -> 0 | AQ17: =IFERROR($AO17/4*(1+$AP$7),0) -> 0 | AR17: =IFERROR($AO17/4*(1+$AP$7),0) -> 0 | AS17: =IFERROR($AO17/4*(1+$AP$7),0) -> 0 | AT17: =SUM(AP17:AS17) -> 0 | AU17: =IFERROR($AT17/4*(1+$AU$7),0) -> 0 | AV17: =IFERROR($AT17/4*(1+$AU$7),0) -> 0 | AW17: =IFERROR($AT17/4*(1+$AU$7),0) -> 0 | AX17: =IFERROR($AT17/4*(1+$AU$7),0) -> 0 | AY17: =SUM(AU17:AX17) -> 0 | AZ17: =IFERROR($AY17/4*(1+$AZ$7),0) -> 0 | BA17: =IFERROR($AY17/4*(1+$AZ$7),0) -> 0 | BB17: =IFERROR($AY17/4*(1+$AZ$7),0) -> 0 | BC17: =IFERROR($AY17/4*(1+$AZ$7),0) -> 0 | BD17: =SUM(AZ17:BC17) -> 0 | BE17: =IFERROR($BD17/4*(1+$BE$7),0) -> 0 | BF17: =IFERROR($BD17/4*(1+$BE$7),0) -> 0 | BG17: =IFERROR($BD17/4*(1+$BE$7),0) -> 0 | BH17: =IFERROR($BD17/4*(1+$BE$7),0) -> 0 | BI17: =SUM(BE17:BH17) -> 0 | BJ17: =IFERROR($BI17/4*(1+$BJ$7),0) -> 0 | BK17: =IFERROR($BI17/4*(1+$BJ$7),0) -> 0 | BL17: =IFERROR($BI17/4*(1+$BJ$7),0) -> 0 | BM17: =IFERROR($BI17/4*(1+$BJ$7),0) -> 0 | BN17: =SUM(BJ17:BM17) -> 0
